Workbook
Name 切片器_平均最低分: #N/A
Name 切片器_2024最低分: #N/A
Name 切片器_2025最低分: #N/A
Name 切片器_类型: #N/A

Sheet 高考志愿填报指南
A1: 100%不滑挡、不退档志愿填报六步法
A2: 第一步：查位次（这是基础中的基础！）不要只看分数，更重要看位次，并按照自己位次*1.05来定位。
A3: 第二步：筛范围（别被众多院校淹没！）
A4: 思路1：圈定地域 你想留在家乡还是去北上广深？或者是向往那些山清水秀的城市？先把低于圈定！
A5: 思路2：筛选院校层次 如果过了本科线，优先关注具有保研资格的370所院校。
A6: 第三步：找标杆（志愿填报的分水岭）什么是标杆院校？就是以你的位次为基准，找到刚好能录取的那所学校！标杆等位分加权计算法则=（2023等效分*40%）+（2022等效分*35%）+（2021等效分*25%）
A7: 标杆院校是你志愿规划的“分水岭”：
A8: .标杆以上的院校=“冲”
A9: .标杆以下的院校=“稳和保”
A10: 第四步：险冲稳保垫兜（志愿填报的黄金配比）这一步是精髓所在！
A11: 我建议的黄金配比是险（10%）、冲（10%）、稳（30%）、保（20%）、垫（10%）、兜（10%）
A12: 【险】志愿（5个）
... A57: “院校+专业组”模式（其余省份）：调剂限于同一专业组内

Sheet 院校录取信息表
A1: 核对备份 不能修改及删除 | D1: 广东春季学考3+证书
C2: 志愿 初选标记 | F2: 2026年广东学考一对一志愿填报 | L2: 填报志愿3月初190公办
F3: 面向高中生 | G3: 分数 | I3: 370 | K3: 位次 | M3: 9367 | R3: 院校信息
D5: 类型 | E5: 院校 代码 | F5: 院校名称 | G5: 专业组代码 | H5: 2025计划数 | I5: 2024计划数 | J5: 2025投档数 | K5: 2024投档数 | L5: 2025最低分 | M5: 2024最低分 | N5: 2025最低位次 | O5: 2024最低位次 | P5: 平均最低分 | Q5: 平均最低位次 | R5: 省份 | S5: 城市 | T5: 院校类型 | U5: 院校层次 | V5: 主管 部门 | W5: 办学 性质 | X5: 城市 水平标签 | Y5: 院校标签 | Z5: 院校 水平 | AA5: 院校简介 | AB5: 历史沿革 | AC5: 学校官网 | AD5: 招生网址 | AE5: 招办电话 | AF5: 院校地址 | AG5: 校园VR | AH5: 院校排名 | AI5: 院校百科 | AJ5: 招生章程
A6: 1 | B6: =C6 -> 1 | C6: 1 | D6: 依据学考 | E6: 11113 | F6: 深圳职业技术大学 | G6: 601 | H6: 449 | I6: 545 | J6: 449 | K6: 545 | L6: 403 | M6: 409 | N6: 2426 | O6: 2276 | P6: =IFERROR(AVERAGE(L6:M6),"/") -> 406 | Q6: =IFERROR(AVERAGE(N6:O6),"/") -> 2351 | R6: 广东省 | S6: 深圳市 | T6: 广东省 | U6: 职业本科 | V6: 广东省 | W6: 公办 | X6: 一线城市 | Y6: 省属/双高计划/高水平学校建设单位/国家级示范 | Z6: 第一类高水平学校A档示范高职 | AA6: 深圳职业技术学院1993年创建，是国内最早独立举办高等职业技术教育的院校之一。建校以来，深职院人艰苦创业，开拓进取，不断创新教育教学理念、办学体制机制和人才培养模式，创造了中国高职教育的多个第一。学校依托珠三角产业发展，秉承深圳特区改革创新精神，坚持把立德树人作为学校教育的根本任务，立足于职业教育产教融合的办学特色，各项事业取得骄人成绩，被誉为中国高职教育的“一面旗帜”。为紧密契合“中国制造2025”等国家重大战略和深圳创新驱动发展战略，学校在2016年底召开的第三次党代会工作报告中提出“三个服务、五个定位、一个率先”的战略发展目标，始终坚持为党和国家服务、为深圳经济社会发展服务、为学生健康成长成才服务，努力成为职业教育创新发展的先行者、复合式创新型高素质技术技能人才的摇篮、企业家的摇篮、深圳中小微企业技术研发中心、深圳市民终身教育学校与中国职业教育师资培训重要基地，率先建成中国特色、世界一流职业院校，为世界职业教育发展贡献“深圳模式”。////学校现有留仙洞、西丽湖、官龙山、华侨城、凤凰山五个校区，校园总面积212万平方米，学校产权校舍建筑面积57.34万平方米，其中教室10.75万平方米，图书馆5万平方米，体育馆3.34万平方米，实训实习场所10.14万平方米。现有固定资产总值23.66亿元，其中教学仪器设备总值9.58亿元,教学用计算机14525台。图书馆藏有纸质图书261.2万册，电子图书130万册，电子期刊60.54万册，中外文数据库46个，音视频16.07万小时。////全校现有教职员工2380人，其中专任教师1243人，正高217人，副高657人，博士408人，享受国务院特殊津贴专家2名，珠江学者5人、海外高层次人才25人、国家“万人计划”教学名师1人、国家级教学名师3人、省级教学名师8人、国家特支计划教师1人、广东特支计划教学名师4人。学校拥有教育部首批黄大年式教师团队1个；引进美国霍夫曼诺奖团队等一批重量级团队，成立霍夫曼先进材料研究院、智能科学与工程研究院、智能制造研究院、新时代中国职业教育研究院、社会与经济发展研究院等高端平台，为珠三角产业发展提供有力支撑。////学校设有电子与通信工程学院等17个二级学院和体育部、工业中心、国际教育部等教学单位，招生专业80个。全校普通全日制在校生22750人，其中港澳台留学生79人，四年制高职生284人，应用型本科生292人，外国留学生127人。自办专科教育在校生3536人。国家级教学成果奖14项，国家职业教育专业教学资源库3项，国家重点支持建设示范专业12个，中央财政支持实训基地9个，国家级精品教材12部，国家精品课程53门，国家级精品资源共享课43门。////学校一直把人才培养作为中心工作，以培养适应智能时代需要的复合式创新型高素质技术技能人才为目标，更新教育教学理念，探索实施以学生学习成效为导向的OBE（Outcome/Based/Education）人才培养模式改革，深入推进产教融合、职普融合、理实融合、技术与文化融合、教育与生活融合、现代信息技术与教学融合等“六个融合”，提升学生的就业能力、职业生涯拓展能力和幸福生活创造能力。瞄准未来社会和经济发展，紧贴深圳四大支柱产业和新兴产业布局专业，打造品牌专业，与华为、ARM、阿里巴巴、平安、比亚迪、裕同、天健等一流企业紧密合作，共建华为信息与网络技术学院、ARM智能硬件学院、阿里巴巴数字贸易学院、平安金融科技学院、比亚迪应用技术学院、裕同数字图文学院、天健建工学院等7所特色产业学院，校企共同制定专业标准、共同开发课程、共建师资团队、共同培养技术技能人才，在服务一流企业中成就自身一流。开设专业文化课程，大力培育工匠精神，厚植工匠文化，全面推进职业院校文化育人。学校已累计培养11万余名全日制专科毕业生，毕业生初次就业率始终保持在96%以上，多项人才培养质量指标位居全国高职院校前列，深受用人单位欢迎。其中，238人次获CCIE证书，13人获RHCA证书，57人获OCM证书，163人获HCIE证书，13人获RHCE证书。////学校探索实施创新创业教育改革，以“五维一体”的创新创业教育理念（重心在“教育”、路径在“分层”、目标在“万众”、核心在“创新”、关键在“实践”）为引领，打造深圳中小微企业技术研发中心、全球技术技能人才创新创业教育中心，以及创新型人才和企业家培养的成长摇篮。通过系统设计、科学构建，协同推进从启蒙教育、预科教育、专门教育到指导创办企业的进阶式创业人才培养体系，搭建“四会两赛三联盟”双创交流平台和“创新型社团—创客中心—学生创意创业园”双创实践平台，逐步完善跨界融合、产品试制、创业孵化、创业投资的双创服务体系，取得良好的社会效益。近年来获评首批全国创新创业典型经验高校、全国深化创新创业教育改革示范高校、广东省大众创业万众创新示范基地、深圳首批十大创新创业基地等。近四届毕业生毕业一年内自主创业比例达到5%，毕业三年后创业比例12.7%。////学校坚持以“产学研用”一体化的科研导向，重视技术转移和科技成果转化。近年来，学校不断深化科研体制机制改革，大力加强与政府职能部门以及行业企业合作，组建成立了应用技术研发院、文化创意产品研发院、经济与社会发展研究院等三大综合性研发平台，建成43个市区级以上科研平台,抢抓产业发展新机遇，服务地方经济社会和中小企业发展。全校累计承担各级各类科研课题5196项，其中国家级项目84项,年度新增国家自然科学基金项目10项。科研经费到账总经费达到8.06亿元，其中技术转移（横向科研）项目到账经费2.98亿元；出版各类学术专著226部、编著、译著和作品集共199部，61项科研成果获部、省、市级奖励；获国家专利授权1726项，软件著作权登记1136件，发明专利345项。主导或参与制定国际、国家、行业标准74项。////学校重视社会服务，发挥品牌优势，致力于推动现代职业教育培训体系和学习型社会建设。做好高水平师资培训，打造世界级的职业教育培训中心；做好职业培训、职业技能鉴定及职业资格认证工作，服务好地方经济发展需要；联合社区街道组建社区学院、特色学院，开展针对社区居民的健康、养老、旅游等培训项目，服务好地方社会发展需要；以办学理念和教学模式输出为主要内容，构建“理念—教学—师资—管理”四位一体的精准帮扶体系，服务好对口支援地区和院校的发展。全年重点对口帮扶11所职业院校，累计对口支援西藏、新疆、贵州等地11个省、自治区的200余所职业院校。全年举办33个全国高职高专师资培训班，累计为全国680余所职业院校培训骨干教师1.2万人次，连续5年名列全国第一。年均开展各类培训、职业技能鉴定与资格认证12万人次。组建西丽社区学院、大鹏旅游学院等社区学院，与社区共同培养技能人才，打造开放办学、产教融合的“职教特区”；选派核心团队建设管理吉安职业技术学院，开创了特区与老区携手共同发展职业教育的典范。////学校紧扣国家发展战略，加快国际化办学步伐，充分利用区域与自身优势，深化国际教育交流与合作。建校以来，已累计与32个国家和地区的162所高校和教育机构建立了友好合作关系，包括英国、德国、法国、美国等发达国家以及新西兰、马来西亚、保加利亚、土耳其、波兰、匈牙利、缅甸、老挝等14个“一带一路”沿线国家。双方在学生交换、课程合作、科研合作、短期研修等领域开展了全方位、多层次、形式多样的教师和学生国际交流活动，取得了丰硕的成果。近年来，我校年均接待境外来访师生及外宾108批次，658人次；我校赴境外参加国际交流的师生52批次，276人次。开办了国际商务（中澳）、金融管理（中澳）、物流管理（中美）和软件技术（中美）4个中外合作办学专业；与香港专业教育学院黄克竞分校合办电气服务工程高级文凭合作课程，毕业生获得深港两地毕业资格，并成为首批获得招收海外留学生资质的高职院校和首个获批面向港澳台自主招生的高职院校。学校还联合中兴、招商港口等一批世界一流企业“走出去”，服务国家“一带一路”倡议。在马来西亚马六甲应用技术大学设立职业教育与培训中心，推动马来西亚全国各类职业院校全面对接深职院标准。依托在保加利亚成立的职业教育与培训中心，输出学校专业标准。应邀为柬埔寨、蒙古等国家职业教育代表团举行专题培训班，输出职业教育经验。加强与职业教育国际组织的合作，成为联合国教科文组织国际职教全球联系中心之一，获批成立联合国教科文组织职业教育计划亚非研究与培训中心。在提高学校国际知名度与影响力的同时，为推动中国职业教育与语言文化走出去做出了积极贡献。////学校办学成绩显著。2001年首家通过国家示范性高职院校实践教学基地优秀评估，2009年通过国家示范性高等职业院校建设项目验收，成为我国高等职业教育领域首批国家级示范校。近年来，学校先后荣获“全国文明单位”、“全国职业教育先进单位”、“全国一流高职院校建设单位”、“首批全国创新创业典型经验高校”、“全国高校毕业生就业工作先进集体”、“中国十大最具就业力高职院校”、“全国毕业生就业工作典型经验高校”、“全国职业院校就业竞争力示范校”、“中国十大创新型高职院校”、“黄炎培优秀学校奖”、“全国高校实践育人创新创业基地”“广东省文明单位”、“广东省职业技术教育工作先进集体”、“广东省首批大学生创新创业教育示范学校”、“广东省一流高职院校建设单位”“深圳市创新创业基地”等荣誉称号。 | AB6: 深圳职业技术大学于1993年创建，前身为深圳职业技术学院，是中国国内最早独立举办高等职业技术教育的院校之一。2000年、2004年原深圳市职业技术学校、深圳市卫生学校分别并入深圳职业技术学院。2006年深圳职业技术学院被确定为“国家示范性高等职业院校建设计划”首批立项建设院校，2009年学校顺利通过验收成为首批国家示范性高等职业院校。2023年6月，教育部发文同意以深圳职业技术学院为基础整合资源设立深圳职业技术大学，同时撤销深圳职业技术学院的建制。 | AC6: http://www.szpt.edu.cn/ | AD6: https://zhaosheng.szpt.edu.cn/ | AE6: 0755/26731715、26731216 | AF6: 深圳市南山区西丽街道留仙大道7098号 | AG6: https://www.720yun.com/t/d8vksm7e0d9 | AH6: 158 | AI6: https://baike.baidu.com/item/%E6%B7%B1%E5%9C%B3%E8%81%8C%E4%B8%9A%E6%8A%80%E6%9C%AF%E5%A4%A7%E5%AD%A6 | AJ6: https://gaokao.chsi.com.cn/zsgs/zhangcheng/listZszc//schId/734.dhtml | AK6: /
A7: 2 | B7: =C7 -> 2 | C7: 2 | D7: 依据学考 | E7: 11113 | F7: 深圳职业技术大学 | G7: 606 | H7: 165 | I7: 221 | J7: 165 | K7: 221 | L7: 396 | M7: 405 | N7: 5357 | O7: 4329 | P7: =IFERROR(AVERAGE(L7:M7),"/") -> 400.5 | Q7: =IFERROR(AVERAGE(N7:O7),"/") -> 4843 | R7: 广东省 | S7: 深圳市 | T7: 广东省 | U7: 职业本科 | V7: 广东省 | W7: 公办 | X7: 一线城市 | Y7: 省属/双高计划/高水平学校建设单位/国家级示范 | Z7: 第一类高水平学校A档示范高职 | AA7: 深圳职业技术学院1993年创建，是国内最早独立举办高等职业技术教育的院校之一。建校以来，深职院人艰苦创业，开拓进取，不断创新教育教学理念、办学体制机制和人才培养模式，创造了中国高职教育的多个第一。学校依托珠三角产业发展，秉承深圳特区改革创新精神，坚持把立德树人作为学校教育的根本任务，立足于职业教育产教融合的办学特色，各项事业取得骄人成绩，被誉为中国高职教育的“一面旗帜”。为紧密契合“中国制造2025”等国家重大战略和深圳创新驱动发展战略，学校在2016年底召开的第三次党代会工作报告中提出“三个服务、五个定位、一个率先”的战略发展目标，始终坚持为党和国家服务、为深圳经济社会发展服务、为学生健康成长成才服务，努力成为职业教育创新发展的先行者、复合式创新型高素质技术技能人才的摇篮、企业家的摇篮、深圳中小微企业技术研发中心、深圳市民终身教育学校与中国职业教育师资培训重要基地，率先建成中国特色、世界一流职业院校，为世界职业教育发展贡献“深圳模式”。////学校现有留仙洞、西丽湖、官龙山、华侨城、凤凰山五个校区，校园总面积212万平方米，学校产权校舍建筑面积57.34万平方米，其中教室10.75万平方米，图书馆5万平方米，体育馆3.34万平方米，实训实习场所10.14万平方米。现有固定资产总值23.66亿元，其中教学仪器设备总值9.58亿元,教学用计算机14525台。图书馆藏有纸质图书261.2万册，电子图书130万册，电子期刊60.54万册，中外文数据库46个，音视频16.07万小时。////全校现有教职员工2380人，其中专任教师1243人，正高217人，副高657人，博士408人，享受国务院特殊津贴专家2名，珠江学者5人、海外高层次人才25人、国家“万人计划”教学名师1人、国家级教学名师3人、省级教学名师8人、国家特支计划教师1人、广东特支计划教学名师4人。学校拥有教育部首批黄大年式教师团队1个；引进美国霍夫曼诺奖团队等一批重量级团队，成立霍夫曼先进材料研究院、智能科学与工程研究院、智能制造研究院、新时代中国职业教育研究院、社会与经济发展研究院等高端平台，为珠三角产业发展提供有力支撑。////学校设有电子与通信工程学院等17个二级学院和体育部、工业中心、国际教育部等教学单位，招生专业80个。全校普通全日制在校生22750人，其中港澳台留学生79人，四年制高职生284人，应用型本科生292人，外国留学生127人。自办专科教育在校生3536人。国家级教学成果奖14项，国家职业教育专业教学资源库3项，国家重点支持建设示范专业12个，中央财政支持实训基地9个，国家级精品教材12部，国家精品课程53门，国家级精品资源共享课43门。////学校一直把人才培养作为中心工作，以培养适应智能时代需要的复合式创新型高素质技术技能人才为目标，更新教育教学理念，探索实施以学生学习成效为导向的OBE（Outcome/Based/Education）人才培养模式改革，深入推进产教融合、职普融合、理实融合、技术与文化融合、教育与生活融合、现代信息技术与教学融合等“六个融合”，提升学生的就业能力、职业生涯拓展能力和幸福生活创造能力。瞄准未来社会和经济发展，紧贴深圳四大支柱产业和新兴产业布局专业，打造品牌专业，与华为、ARM、阿里巴巴、平安、比亚迪、裕同、天健等一流企业紧密合作，共建华为信息与网络技术学院、ARM智能硬件学院、阿里巴巴数字贸易学院、平安金融科技学院、比亚迪应用技术学院、裕同数字图文学院、天健建工学院等7所特色产业学院，校企共同制定专业标准、共同开发课程、共建师资团队、共同培养技术技能人才，在服务一流企业中成就自身一流。开设专业文化课程，大力培育工匠精神，厚植工匠文化，全面推进职业院校文化育人。学校已累计培养11万余名全日制专科毕业生，毕业生初次就业率始终保持在96%以上，多项人才培养质量指标位居全国高职院校前列，深受用人单位欢迎。其中，238人次获CCIE证书，13人获RHCA证书，57人获OCM证书，163人获HCIE证书，13人获RHCE证书。////学校探索实施创新创业教育改革，以“五维一体”的创新创业教育理念（重心在“教育”、路径在“分层”、目标在“万众”、核心在“创新”、关键在“实践”）为引领，打造深圳中小微企业技术研发中心、全球技术技能人才创新创业教育中心，以及创新型人才和企业家培养的成长摇篮。通过系统设计、科学构建，协同推进从启蒙教育、预科教育、专门教育到指导创办企业的进阶式创业人才培养体系，搭建“四会两赛三联盟”双创交流平台和“创新型社团—创客中心—学生创意创业园”双创实践平台，逐步完善跨界融合、产品试制、创业孵化、创业投资的双创服务体系，取得良好的社会效益。近年来获评首批全国创新创业典型经验高校、全国深化创新创业教育改革示范高校、广东省大众创业万众创新示范基地、深圳首批十大创新创业基地等。近四届毕业生毕业一年内自主创业比例达到5%，毕业三年后创业比例12.7%。////学校坚持以“产学研用”一体化的科研导向，重视技术转移和科技成果转化。近年来，学校不断深化科研体制机制改革，大力加强与政府职能部门以及行业企业合作，组建成立了应用技术研发院、文化创意产品研发院、经济与社会发展研究院等三大综合性研发平台，建成43个市区级以上科研平台,抢抓产业发展新机遇，服务地方经济社会和中小企业发展。全校累计承担各级各类科研课题5196项，其中国家级项目84项,年度新增国家自然科学基金项目10项。科研经费到账总经费达到8.06亿元，其中技术转移（横向科研）项目到账经费2.98亿元；出版各类学术专著226部、编著、译著和作品集共199部，61项科研成果获部、省、市级奖励；获国家专利授权1726项，软件著作权登记1136件，发明专利345项。主导或参与制定国际、国家、行业标准74项。////学校重视社会服务，发挥品牌优势，致力于推动现代职业教育培训体系和学习型社会建设。做好高水平师资培训，打造世界级的职业教育培训中心；做好职业培训、职业技能鉴定及职业资格认证工作，服务好地方经济发展需要；联合社区街道组建社区学院、特色学院，开展针对社区居民的健康、养老、旅游等培训项目，服务好地方社会发展需要；以办学理念和教学模式输出为主要内容，构建“理念—教学—师资—管理”四位一体的精准帮扶体系，服务好对口支援地区和院校的发展。全年重点对口帮扶11所职业院校，累计对口支援西藏、新疆、贵州等地11个省、自治区的200余所职业院校。全年举办33个全国高职高专师资培训班，累计为全国680余所职业院校培训骨干教师1.2万人次，连续5年名列全国第一。年均开展各类培训、职业技能鉴定与资格认证12万人次。组建西丽社区学院、大鹏旅游学院等社区学院，与社区共同培养技能人才，打造开放办学、产教融合的“职教特区”；选派核心团队建设管理吉安职业技术学院，开创了特区与老区携手共同发展职业教育的典范。////学校紧扣国家发展战略，加快国际化办学步伐，充分利用区域与自身优势，深化国际教育交流与合作。建校以来，已累计与32个国家和地区的162所高校和教育机构建立了友好合作关系，包括英国、德国、法国、美国等发达国家以及新西兰、马来西亚、保加利亚、土耳其、波兰、匈牙利、缅甸、老挝等14个“一带一路”沿线国家。双方在学生交换、课程合作、科研合作、短期研修等领域开展了全方位、多层次、形式多样的教师和学生国际交流活动，取得了丰硕的成果。近年来，我校年均接待境外来访师生及外宾108批次，658人次；我校赴境外参加国际交流的师生52批次，276人次。开办了国际商务（中澳）、金融管理（中澳）、物流管理（中美）和软件技术（中美）4个中外合作办学专业；与香港专业教育学院黄克竞分校合办电气服务工程高级文凭合作课程，毕业生获得深港两地毕业资格，并成为首批获得招收海外留学生资质的高职院校和首个获批面向港澳台自主招生的高职院校。学校还联合中兴、招商港口等一批世界一流企业“走出去”，服务国家“一带一路”倡议。在马来西亚马六甲应用技术大学设立职业教育与培训中心，推动马来西亚全国各类职业院校全面对接深职院标准。依托在保加利亚成立的职业教育与培训中心，输出学校专业标准。应邀为柬埔寨、蒙古等国家职业教育代表团举行专题培训班，输出职业教育经验。加强与职业教育国际组织的合作，成为联合国教科文组织国际职教全球联系中心之一，获批成立联合国教科文组织职业教育计划亚非研究与培训中心。在提高学校国际知名度与影响力的同时，为推动中国职业教育与语言文化走出去做出了积极贡献。////学校办学成绩显著。2001年首家通过国家示范性高职院校实践教学基地优秀评估，2009年通过国家示范性高等职业院校建设项目验收，成为我国高等职业教育领域首批国家级示范校。近年来，学校先后荣获“全国文明单位”、“全国职业教育先进单位”、“全国一流高职院校建设单位”、“首批全国创新创业典型经验高校”、“全国高校毕业生就业工作先进集体”、“中国十大最具就业力高职院校”、“全国毕业生就业工作典型经验高校”、“全国职业院校就业竞争力示范校”、“中国十大创新型高职院校”、“黄炎培优秀学校奖”、“全国高校实践育人创新创业基地”“广东省文明单位”、“广东省职业技术教育工作先进集体”、“广东省首批大学生创新创业教育示范学校”、“广东省一流高职院校建设单位”“深圳市创新创业基地”等荣誉称号。 | AB7: 深圳职业技术大学于1993年创建，前身为深圳职业技术学院，是中国国内最早独立举办高等职业技术教育的院校之一。2000年、2004年原深圳市职业技术学校、深圳市卫生学校分别并入深圳职业技术学院。2006年深圳职业技术学院被确定为“国家示范性高等职业院校建设计划”首批立项建设院校，2009年学校顺利通过验收成为首批国家示范性高等职业院校。2023年6月，教育部发文同意以深圳职业技术学院为基础整合资源设立深圳职业技术大学，同时撤销深圳职业技术学院的建制。 | AC7: http://www.szpt.edu.cn/ | AD7: https://zhaosheng.szpt.edu.cn/ | AE7: 0755/26731715、26731216 | AF7: 深圳市南山区西丽街道留仙大道7098号 | AG7: https://www.720yun.com/t/d8vksm7e0d9 | AH7: 158 | AI7: https://baike.baidu.com/item/%E6%B7%B1%E5%9C%B3%E8%81%8C%E4%B8%9A%E6%8A%80%E6%9C%AF%E5%A4%A7%E5%AD%A6 | AJ7: https://gaokao.chsi.com.cn/zsgs/zhangcheng/listZszc//schId/734.dhtml | AK7: /
A8: 3 | B8: =C8 -> 3 | C8: 3 | D8: 依据学考 | E8: 11113 | F8: 深圳职业技术大学 | G8: 602 | H8: 500 | I8: 607 | J8: 500 | K8: 608 | L8: 397 | M8: 403 | N8: 5171 | O8: 5580 | P8: =IFERROR(AVERAGE(L8:M8),"/") -> 400 | Q8: =IFERROR(AVERAGE(N8:O8),"/") -> 5375.5 | R8: 广东省 | S8: 深圳市 | T8: 广东省 | U8: 职业本科 | V8: 广东省 | W8: 公办 | X8: 一线城市 | Y8: 省属/双高计划/高水平学校建设单位/国家级示范 | Z8: 第一类高水平学校A档示范高职 | AA8: 深圳职业技术学院1993年创建，是国内最早独立举办高等职业技术教育的院校之一。建校以来，深职院人艰苦创业，开拓进取，不断创新教育教学理念、办学体制机制和人才培养模式，创造了中国高职教育的多个第一。学校依托珠三角产业发展，秉承深圳特区改革创新精神，坚持把立德树人作为学校教育的根本任务，立足于职业教育产教融合的办学特色，各项事业取得骄人成绩，被誉为中国高职教育的“一面旗帜”。为紧密契合“中国制造2025”等国家重大战略和深圳创新驱动发展战略，学校在2016年底召开的第三次党代会工作报告中提出“三个服务、五个定位、一个率先”的战略发展目标，始终坚持为党和国家服务、为深圳经济社会发展服务、为学生健康成长成才服务，努力成为职业教育创新发展的先行者、复合式创新型高素质技术技能人才的摇篮、企业家的摇篮、深圳中小微企业技术研发中心、深圳市民终身教育学校与中国职业教育师资培训重要基地，率先建成中国特色、世界一流职业院校，为世界职业教育发展贡献“深圳模式”。////学校现有留仙洞、西丽湖、官龙山、华侨城、凤凰山五个校区，校园总面积212万平方米，学校产权校舍建筑面积57.34万平方米，其中教室10.75万平方米，图书馆5万平方米，体育馆3.34万平方米，实训实习场所10.14万平方米。现有固定资产总值23.66亿元，其中教学仪器设备总值9.58亿元,教学用计算机14525台。图书馆藏有纸质图书261.2万册，电子图书130万册，电子期刊60.54万册，中外文数据库46个，音视频16.07万小时。////全校现有教职员工2380人，其中专任教师1243人，正高217人，副高657人，博士408人，享受国务院特殊津贴专家2名，珠江学者5人、海外高层次人才25人、国家“万人计划”教学名师1人、国家级教学名师3人、省级教学名师8人、国家特支计划教师1人、广东特支计划教学名师4人。学校拥有教育部首批黄大年式教师团队1个；引进美国霍夫曼诺奖团队等一批重量级团队，成立霍夫曼先进材料研究院、智能科学与工程研究院、智能制造研究院、新时代中国职业教育研究院、社会与经济发展研究院等高端平台，为珠三角产业发展提供有力支撑。////学校设有电子与通信工程学院等17个二级学院和体育部、工业中心、国际教育部等教学单位，招生专业80个。全校普通全日制在校生22750人，其中港澳台留学生79人，四年制高职生284人，应用型本科生292人，外国留学生127人。自办专科教育在校生3536人。国家级教学成果奖14项，国家职业教育专业教学资源库3项，国家重点支持建设示范专业12个，中央财政支持实训基地9个，国家级精品教材12部，国家精品课程53门，国家级精品资源共享课43门。////学校一直把人才培养作为中心工作，以培养适应智能时代需要的复合式创新型高素质技术技能人才为目标，更新教育教学理念，探索实施以学生学习成效为导向的OBE（Outcome/Based/Education）人才培养模式改革，深入推进产教融合、职普融合、理实融合、技术与文化融合、教育与生活融合、现代信息技术与教学融合等“六个融合”，提升学生的就业能力、职业生涯拓展能力和幸福生活创造能力。瞄准未来社会和经济发展，紧贴深圳四大支柱产业和新兴产业布局专业，打造品牌专业，与华为、ARM、阿里巴巴、平安、比亚迪、裕同、天健等一流企业紧密合作，共建华为信息与网络技术学院、ARM智能硬件学院、阿里巴巴数字贸易学院、平安金融科技学院、比亚迪应用技术学院、裕同数字图文学院、天健建工学院等7所特色产业学院，校企共同制定专业标准、共同开发课程、共建师资团队、共同培养技术技能人才，在服务一流企业中成就自身一流。开设专业文化课程，大力培育工匠精神，厚植工匠文化，全面推进职业院校文化育人。学校已累计培养11万余名全日制专科毕业生，毕业生初次就业率始终保持在96%以上，多项人才培养质量指标位居全国高职院校前列，深受用人单位欢迎。其中，238人次获CCIE证书，13人获RHCA证书，57人获OCM证书，163人获HCIE证书，13人获RHCE证书。////学校探索实施创新创业教育改革，以“五维一体”的创新创业教育理念（重心在“教育”、路径在“分层”、目标在“万众”、核心在“创新”、关键在“实践”）为引领，打造深圳中小微企业技术研发中心、全球技术技能人才创新创业教育中心，以及创新型人才和企业家培养的成长摇篮。通过系统设计、科学构建，协同推进从启蒙教育、预科教育、专门教育到指导创办企业的进阶式创业人才培养体系，搭建“四会两赛三联盟”双创交流平台和“创新型社团—创客中心—学生创意创业园”双创实践平台，逐步完善跨界融合、产品试制、创业孵化、创业投资的双创服务体系，取得良好的社会效益。近年来获评首批全国创新创业典型经验高校、全国深化创新创业教育改革示范高校、广东省大众创业万众创新示范基地、深圳首批十大创新创业基地等。近四届毕业生毕业一年内自主创业比例达到5%，毕业三年后创业比例12.7%。////学校坚持以“产学研用”一体化的科研导向，重视技术转移和科技成果转化。近年来，学校不断深化科研体制机制改革，大力加强与政府职能部门以及行业企业合作，组建成立了应用技术研发院、文化创意产品研发院、经济与社会发展研究院等三大综合性研发平台，建成43个市区级以上科研平台,抢抓产业发展新机遇，服务地方经济社会和中小企业发展。全校累计承担各级各类科研课题5196项，其中国家级项目84项,年度新增国家自然科学基金项目10项。科研经费到账总经费达到8.06亿元，其中技术转移（横向科研）项目到账经费2.98亿元；出版各类学术专著226部、编著、译著和作品集共199部，61项科研成果获部、省、市级奖励；获国家专利授权1726项，软件著作权登记1136件，发明专利345项。主导或参与制定国际、国家、行业标准74项。////学校重视社会服务，发挥品牌优势，致力于推动现代职业教育培训体系和学习型社会建设。做好高水平师资培训，打造世界级的职业教育培训中心；做好职业培训、职业技能鉴定及职业资格认证工作，服务好地方经济发展需要；联合社区街道组建社区学院、特色学院，开展针对社区居民的健康、养老、旅游等培训项目，服务好地方社会发展需要；以办学理念和教学模式输出为主要内容，构建“理念—教学—师资—管理”四位一体的精准帮扶体系，服务好对口支援地区和院校的发展。全年重点对口帮扶11所职业院校，累计对口支援西藏、新疆、贵州等地11个省、自治区的200余所职业院校。全年举办33个全国高职高专师资培训班，累计为全国680余所职业院校培训骨干教师1.2万人次，连续5年名列全国第一。年均开展各类培训、职业技能鉴定与资格认证12万人次。组建西丽社区学院、大鹏旅游学院等社区学院，与社区共同培养技能人才，打造开放办学、产教融合的“职教特区”；选派核心团队建设管理吉安职业技术学院，开创了特区与老区携手共同发展职业教育的典范。////学校紧扣国家发展战略，加快国际化办学步伐，充分利用区域与自身优势，深化国际教育交流与合作。建校以来，已累计与32个国家和地区的162所高校和教育机构建立了友好合作关系，包括英国、德国、法国、美国等发达国家以及新西兰、马来西亚、保加利亚、土耳其、波兰、匈牙利、缅甸、老挝等14个“一带一路”沿线国家。双方在学生交换、课程合作、科研合作、短期研修等领域开展了全方位、多层次、形式多样的教师和学生国际交流活动，取得了丰硕的成果。近年来，我校年均接待境外来访师生及外宾108批次，658人次；我校赴境外参加国际交流的师生52批次，276人次。开办了国际商务（中澳）、金融管理（中澳）、物流管理（中美）和软件技术（中美）4个中外合作办学专业；与香港专业教育学院黄克竞分校合办电气服务工程高级文凭合作课程，毕业生获得深港两地毕业资格，并成为首批获得招收海外留学生资质的高职院校和首个获批面向港澳台自主招生的高职院校。学校还联合中兴、招商港口等一批世界一流企业“走出去”，服务国家“一带一路”倡议。在马来西亚马六甲应用技术大学设立职业教育与培训中心，推动马来西亚全国各类职业院校全面对接深职院标准。依托在保加利亚成立的职业教育与培训中心，输出学校专业标准。应邀为柬埔寨、蒙古等国家职业教育代表团举行专题培训班，输出职业教育经验。加强与职业教育国际组织的合作，成为联合国教科文组织国际职教全球联系中心之一，获批成立联合国教科文组织职业教育计划亚非研究与培训中心。在提高学校国际知名度与影响力的同时，为推动中国职业教育与语言文化走出去做出了积极贡献。////学校办学成绩显著。2001年首家通过国家示范性高职院校实践教学基地优秀评估，2009年通过国家示范性高等职业院校建设项目验收，成为我国高等职业教育领域首批国家级示范校。近年来，学校先后荣获“全国文明单位”、“全国职业教育先进单位”、“全国一流高职院校建设单位”、“首批全国创新创业典型经验高校”、“全国高校毕业生就业工作先进集体”、“中国十大最具就业力高职院校”、“全国毕业生就业工作典型经验高校”、“全国职业院校就业竞争力示范校”、“中国十大创新型高职院校”、“黄炎培优秀学校奖”、“全国高校实践育人创新创业基地”“广东省文明单位”、“广东省职业技术教育工作先进集体”、“广东省首批大学生创新创业教育示范学校”、“广东省一流高职院校建设单位”“深圳市创新创业基地”等荣誉称号。 | AB8: 深圳职业技术大学于1993年创建，前身为深圳职业技术学院，是中国国内最早独立举办高等职业技术教育的院校之一。2000年、2004年原深圳市职业技术学校、深圳市卫生学校分别并入深圳职业技术学院。2006年深圳职业技术学院被确定为“国家示范性高等职业院校建设计划”首批立项建设院校，2009年学校顺利通过验收成为首批国家示范性高等职业院校。2023年6月，教育部发文同意以深圳职业技术学院为基础整合资源设立深圳职业技术大学，同时撤销深圳职业技术学院的建制。 | AC8: http://www.szpt.edu.cn/ | AD8: https://zhaosheng.szpt.edu.cn/ | AE8: 0755/26731715、26731216 | AF8: 深圳市南山区西丽街道留仙大道7098号 | AG8: https://www.720yun.com/t/d8vksm7e0d9 | AH8: 158 | AI8: https://baike.baidu.com/item/%E6%B7%B1%E5%9C%B3%E8%81%8C%E4%B8%9A%E6%8A%80%E6%9C%AF%E5%A4%A7%E5%AD%A6 | AJ8: https://gaokao.chsi.com.cn/zsgs/zhangcheng/listZszc//schId/734.dhtml | AK8: /
A9: 4 | B9: =C9 -> 4 | C9: 4 | D9: 依据学考 | E9: 11113 | F9: 深圳职业技术大学 | G9: 607 | H9: 229 | I9: 258 | J9: 229 | K9: 259 | L9: 394 | M9: 403 | N9: 6763 | O9: 6133 | P9: =IFERROR(AVERAGE(L9:M9),"/") -> 398.5 | Q9: =IFERROR(AVERAGE(N9:O9),"/") -> 6448 | R9: 广东省 | S9: 深圳市 | T9: 广东省 | U9: 职业本科 | V9: 广东省 | W9: 公办 | X9: 一线城市 | Y9: 省属/双高计划/高水平学校建设单位/国家级示范 | Z9: 第一类高水平学校A档示范高职 | AA9: 深圳职业技术学院1993年创建，是国内最早独立举办高等职业技术教育的院校之一。建校以来，深职院人艰苦创业，开拓进取，不断创新教育教学理念、办学体制机制和人才培养模式，创造了中国高职教育的多个第一。学校依托珠三角产业发展，秉承深圳特区改革创新精神，坚持把立德树人作为学校教育的根本任务，立足于职业教育产教融合的办学特色，各项事业取得骄人成绩，被誉为中国高职教育的“一面旗帜”。为紧密契合“中国制造2025”等国家重大战略和深圳创新驱动发展战略，学校在2016年底召开的第三次党代会工作报告中提出“三个服务、五个定位、一个率先”的战略发展目标，始终坚持为党和国家服务、为深圳经济社会发展服务、为学生健康成长成才服务，努力成为职业教育创新发展的先行者、复合式创新型高素质技术技能人才的摇篮、企业家的摇篮、深圳中小微企业技术研发中心、深圳市民终身教育学校与中国职业教育师资培训重要基地，率先建成中国特色、世界一流职业院校，为世界职业教育发展贡献“深圳模式”。////学校现有留仙洞、西丽湖、官龙山、华侨城、凤凰山五个校区，校园总面积212万平方米，学校产权校舍建筑面积57.34万平方米，其中教室10.75万平方米，图书馆5万平方米，体育馆3.34万平方米，实训实习场所10.14万平方米。现有固定资产总值23.66亿元，其中教学仪器设备总值9.58亿元,教学用计算机14525台。图书馆藏有纸质图书261.2万册，电子图书130万册，电子期刊60.54万册，中外文数据库46个，音视频16.07万小时。////全校现有教职员工2380人，其中专任教师1243人，正高217人，副高657人，博士408人，享受国务院特殊津贴专家2名，珠江学者5人、海外高层次人才25人、国家“万人计划”教学名师1人、国家级教学名师3人、省级教学名师8人、国家特支计划教师1人、广东特支计划教学名师4人。学校拥有教育部首批黄大年式教师团队1个；引进美国霍夫曼诺奖团队等一批重量级团队，成立霍夫曼先进材料研究院、智能科学与工程研究院、智能制造研究院、新时代中国职业教育研究院、社会与经济发展研究院等高端平台，为珠三角产业发展提供有力支撑。////学校设有电子与通信工程学院等17个二级学院和体育部、工业中心、国际教育部等教学单位，招生专业80个。全校普通全日制在校生22750人，其中港澳台留学生79人，四年制高职生284人，应用型本科生292人，外国留学生127人。自办专科教育在校生3536人。国家级教学成果奖14项，国家职业教育专业教学资源库3项，国家重点支持建设示范专业12个，中央财政支持实训基地9个，国家级精品教材12部，国家精品课程53门，国家级精品资源共享课43门。////学校一直把人才培养作为中心工作，以培养适应智能时代需要的复合式创新型高素质技术技能人才为目标，更新教育教学理念，探索实施以学生学习成效为导向的OBE（Outcome/Based/Education）人才培养模式改革，深入推进产教融合、职普融合、理实融合、技术与文化融合、教育与生活融合、现代信息技术与教学融合等“六个融合”，提升学生的就业能力、职业生涯拓展能力和幸福生活创造能力。瞄准未来社会和经济发展，紧贴深圳四大支柱产业和新兴产业布局专业，打造品牌专业，与华为、ARM、阿里巴巴、平安、比亚迪、裕同、天健等一流企业紧密合作，共建华为信息与网络技术学院、ARM智能硬件学院、阿里巴巴数字贸易学院、平安金融科技学院、比亚迪应用技术学院、裕同数字图文学院、天健建工学院等7所特色产业学院，校企共同制定专业标准、共同开发课程、共建师资团队、共同培养技术技能人才，在服务一流企业中成就自身一流。开设专业文化课程，大力培育工匠精神，厚植工匠文化，全面推进职业院校文化育人。学校已累计培养11万余名全日制专科毕业生，毕业生初次就业率始终保持在96%以上，多项人才培养质量指标位居全国高职院校前列，深受用人单位欢迎。其中，238人次获CCIE证书，13人获RHCA证书，57人获OCM证书，163人获HCIE证书，13人获RHCE证书。////学校探索实施创新创业教育改革，以“五维一体”的创新创业教育理念（重心在“教育”、路径在“分层”、目标在“万众”、核心在“创新”、关键在“实践”）为引领，打造深圳中小微企业技术研发中心、全球技术技能人才创新创业教育中心，以及创新型人才和企业家培养的成长摇篮。通过系统设计、科学构建，协同推进从启蒙教育、预科教育、专门教育到指导创办企业的进阶式创业人才培养体系，搭建“四会两赛三联盟”双创交流平台和“创新型社团—创客中心—学生创意创业园”双创实践平台，逐步完善跨界融合、产品试制、创业孵化、创业投资的双创服务体系，取得良好的社会效益。近年来获评首批全国创新创业典型经验高校、全国深化创新创业教育改革示范高校、广东省大众创业万众创新示范基地、深圳首批十大创新创业基地等。近四届毕业生毕业一年内自主创业比例达到5%，毕业三年后创业比例12.7%。////学校坚持以“产学研用”一体化的科研导向，重视技术转移和科技成果转化。近年来，学校不断深化科研体制机制改革，大力加强与政府职能部门以及行业企业合作，组建成立了应用技术研发院、文化创意产品研发院、经济与社会发展研究院等三大综合性研发平台，建成43个市区级以上科研平台,抢抓产业发展新机遇，服务地方经济社会和中小企业发展。全校累计承担各级各类科研课题5196项，其中国家级项目84项,年度新增国家自然科学基金项目10项。科研经费到账总经费达到8.06亿元，其中技术转移（横向科研）项目到账经费2.98亿元；出版各类学术专著226部、编著、译著和作品集共199部，61项科研成果获部、省、市级奖励；获国家专利授权1726项，软件著作权登记1136件，发明专利345项。主导或参与制定国际、国家、行业标准74项。////学校重视社会服务，发挥品牌优势，致力于推动现代职业教育培训体系和学习型社会建设。做好高水平师资培训，打造世界级的职业教育培训中心；做好职业培训、职业技能鉴定及职业资格认证工作，服务好地方经济发展需要；联合社区街道组建社区学院、特色学院，开展针对社区居民的健康、养老、旅游等培训项目，服务好地方社会发展需要；以办学理念和教学模式输出为主要内容，构建“理念—教学—师资—管理”四位一体的精准帮扶体系，服务好对口支援地区和院校的发展。全年重点对口帮扶11所职业院校，累计对口支援西藏、新疆、贵州等地11个省、自治区的200余所职业院校。全年举办33个全国高职高专师资培训班，累计为全国680余所职业院校培训骨干教师1.2万人次，连续5年名列全国第一。年均开展各类培训、职业技能鉴定与资格认证12万人次。组建西丽社区学院、大鹏旅游学院等社区学院，与社区共同培养技能人才，打造开放办学、产教融合的“职教特区”；选派核心团队建设管理吉安职业技术学院，开创了特区与老区携手共同发展职业教育的典范。////学校紧扣国家发展战略，加快国际化办学步伐，充分利用区域与自身优势，深化国际教育交流与合作。建校以来，已累计与32个国家和地区的162所高校和教育机构建立了友好合作关系，包括英国、德国、法国、美国等发达国家以及新西兰、马来西亚、保加利亚、土耳其、波兰、匈牙利、缅甸、老挝等14个“一带一路”沿线国家。双方在学生交换、课程合作、科研合作、短期研修等领域开展了全方位、多层次、形式多样的教师和学生国际交流活动，取得了丰硕的成果。近年来，我校年均接待境外来访师生及外宾108批次，658人次；我校赴境外参加国际交流的师生52批次，276人次。开办了国际商务（中澳）、金融管理（中澳）、物流管理（中美）和软件技术（中美）4个中外合作办学专业；与香港专业教育学院黄克竞分校合办电气服务工程高级文凭合作课程，毕业生获得深港两地毕业资格，并成为首批获得招收海外留学生资质的高职院校和首个获批面向港澳台自主招生的高职院校。学校还联合中兴、招商港口等一批世界一流企业“走出去”，服务国家“一带一路”倡议。在马来西亚马六甲应用技术大学设立职业教育与培训中心，推动马来西亚全国各类职业院校全面对接深职院标准。依托在保加利亚成立的职业教育与培训中心，输出学校专业标准。应邀为柬埔寨、蒙古等国家职业教育代表团举行专题培训班，输出职业教育经验。加强与职业教育国际组织的合作，成为联合国教科文组织国际职教全球联系中心之一，获批成立联合国教科文组织职业教育计划亚非研究与培训中心。在提高学校国际知名度与影响力的同时，为推动中国职业教育与语言文化走出去做出了积极贡献。////学校办学成绩显著。2001年首家通过国家示范性高职院校实践教学基地优秀评估，2009年通过国家示范性高等职业院校建设项目验收，成为我国高等职业教育领域首批国家级示范校。近年来，学校先后荣获“全国文明单位”、“全国职业教育先进单位”、“全国一流高职院校建设单位”、“首批全国创新创业典型经验高校”、“全国高校毕业生就业工作先进集体”、“中国十大最具就业力高职院校”、“全国毕业生就业工作典型经验高校”、“全国职业院校就业竞争力示范校”、“中国十大创新型高职院校”、“黄炎培优秀学校奖”、“全国高校实践育人创新创业基地”“广东省文明单位”、“广东省职业技术教育工作先进集体”、“广东省首批大学生创新创业教育示范学校”、“广东省一流高职院校建设单位”“深圳市创新创业基地”等荣誉称号。 | AB9: 深圳职业技术大学于1993年创建，前身为深圳职业技术学院，是中国国内最早独立举办高等职业技术教育的院校之一。2000年、2004年原深圳市职业技术学校、深圳市卫生学校分别并入深圳职业技术学院。2006年深圳职业技术学院被确定为“国家示范性高等职业院校建设计划”首批立项建设院校，2009年学校顺利通过验收成为首批国家示范性高等职业院校。2023年6月，教育部发文同意以深圳职业技术学院为基础整合资源设立深圳职业技术大学，同时撤销深圳职业技术学院的建制。 | AC9: http://www.szpt.edu.cn/ | AD9: https://zhaosheng.szpt.edu.cn/ | AE9: 0755/26731715、26731216 | AF9: 深圳市南山区西丽街道留仙大道7098号 | AG9: https://www.720yun.com/t/d8vksm7e0d9 | AH9: 158 | AI9: https://baike.baidu.com/item/%E6%B7%B1%E5%9C%B3%E8%81%8C%E4%B8%9A%E6%8A%80%E6%9C%AF%E5%A4%A7%E5%AD%A6 | AJ9: https://gaokao.chsi.com.cn/zsgs/zhangcheng/listZszc//schId/734.dhtml | AK9: /
A10: 5 | B10: =C10 -> 5 | C10: 5 | D10: 依据学考 | E10: 12957 | F10: 深圳信息职业技术大学 | G10: 602 | H10: 219 | I10: 172 | J10: 219 | K10: 174 | L10: 391 | M10: 402 | N10: 8461 | O10: 6626 | P10: =IFERROR(AVERAGE(L10:M10),"/") -> 396.5 | Q10: =IFERROR(AVERAGE(N10:O10),"/") -> 7543.5 | R10: 广东省 | S10: 深圳市 | T10: 广东省 | U10: 职业本科 | V10: 广东省 | W10: 公办 | X10: 一线城市 | Y10: 双高计划/高水平学校建设单位/国家级骨干/现代学徒制试点学院 | Z10: 第二类高水平学校B档骨干高职现代学徒 | AA10: 深圳信息职业技术学院创办于2002年4月，是经广东省人民政府批准、教育部备案，由深圳市人民政府举办的公办全日制高等院校。//学校现为国家示范（骨干）高职院校、国家示范性软件职业技术学院、教育部“中德职教汽车机电合作项目”试点院校，现拥有3个国家级高等职业教育专业教学资源库（含1个备选项目）。学校拥有现代化、生态型、信息化的校园，占地92.6万平方米（1389亩），建筑面积58.86万平方米。学校现有教学科研仪器设备总值为36786.36万元，图书馆藏书131.33万册。//学校对接深圳支柱产业，打造信息技术特色，共设软件学院、电子与通信学院、计算机学院、数字媒体学院、智能制造与装备学院、交通与环境学院、管理学院、财经学院、应用外语学院、中德学院、马克思主义学院、继续教育学院、创新创业学院、创新教育研究院、公共课教学部、体育部、信息技术研究所等14院2部1所；开设信息类为主的专业44个。现有国家骨干校重点建设专业4个，国家高等职业学校提升专业服务产业发展能力建设专业2个，全国职业院校示范专业点2个，国家高等职业教育教学资源库建设项目3个（含1个备选项目），广东省示范性专业4个，省级重点建设专业6个，省级品牌专业11个；国家级精品资源共享课7门、省级精品资源共享课（含精品在线开放课）38门、省级思想政治理论优质建设课程2门。//学校现有教职工796人，在590位专任教师中，副高及以上职称教师301人，其中，博士、博士后275人，“双师素质”教师九成。目前，学校拥有国家级教学团队1个，获国家级教学名师奖1人，获全国五一劳动奖章1人，国家万人计划教学名师1名，广东省教学名师奖3人，广东省“特支计划”教学名师3人，省级教学团队7个，南粤优秀教师7人，广东省“千百十人才培养工程”省级培养对象6人，广东省“珠江学者”特聘教授4人，深圳市“鹏城学者”特聘教授3人，深圳市政府特殊津贴1人，黄炎培职业教育杰出教师奖1人，深圳市高层次专业人才地方级领军人才9名，后备级领军人才21人，博士后创新实践基地在站博士后3人。//学校坚持科研引领、教研创新、突出应用、服务社会。已主持国家自然科学基金等国家级项目26项、省市级科研项目517项，教研课题国家级6项、省市级49项，深圳市首批教育科研专家工作室1个。获得国家级高等学校教学成果一等奖1项、二等奖2项，省级教学成果一等奖6项、二等奖4项，广东省科学技术二等奖2项、三等奖2项，国家教师科研基金“十一五”规划重点课题科研成果一等奖1项，深圳市科技进步奖2项，深圳市科技创新奖2项，深圳市科学技术奖自然科学奖1项，深圳市哲学社会科学优秀成果奖7项，中国人工智能学会进步奖二等奖；拥有发明专利62项，实用新型专利203项，外观设计专利8项。//学校坚持校企合作办学，积极推进产教融合协同育人，创新合作办学机制，探索校企合作模式，在校内构建了“三会两办”的办学机制，并打造了“学院+行业企业”的校企合作模式。学校用2万平米实训场地，引企入校，合作共建实践教学基地、科技创新平台等，基地目前建有2个省级创新平台、1个先进土木研究中心、1个智能制造实训中心、5个校级协同创新中心等创新载体。学校有国家级高等职业教育实训基地2个，省级高等职业教育实训基地11个，省级公共实训中心1个，省级大学生校外实践教学基地12个，深圳市高职教育校外公共实训基地33个。//学校建构高素质高技能人才培养机制，不断提升高就业率、高满意度办学效益。现有全日制在校生15468人，学校坚持产教融合、校企合作、因材施教、特色发展。近三年，学生参加专业技能竞赛共获国家级奖项137个，省级二等奖以上315个。毕业生“下得去、留得住、用得上、干得好”，毕业生总体就业率均在98%以上。毕业生被华为、腾讯、深圳地铁、中国联通等著名企业录用，产生了被《华尔街日报》报道为“中国最年轻90后千万富豪”丁仕源、拥有8家公司的速运邦邦CEO陈家良等创业典型。//学校积极引进国际先进教学资源，不断形成国际化办学特色。2012年，学校成为教育部“中德职教汽车机电合作项目”试点院校；2013年11月学校与西双版纳职业技术学院正式签署合作协议共建“深圳信息/西双版纳国际留学生基地”/并揭牌；2016年9月，由深圳市教育局和德国巴伐利亚州文教部推动，我校与德国巴伐利亚州帕绍技术学校、兰茨胡特应用技术大学合作创办中德学院；2018年5月，学校与芬兰于韦斯屈莱应用科技大学签订战略合作协议全面启动两校战略合作项目；此外，学校还与加拿大谢尔丹理工学院、韩国京畿大学、台湾地区朝阳科技大学、树德科技大学、龙华科技大学、台北城市科技大学、亚太创意技术学院等26所高校开展了师生交流、合作科研等项目。//学校跨越发展，已跻身全国高职院校“第一方阵”。2004年，学校成为“国家示范性软件职业技术学院”建设院校；2007年，以优异成绩通过教育部人才培养工作水平评估；2010年，成为国家骨干高职院校建设单位；2011年，获国家高等职业教育网络技术专业共享型教学资源库建设立项；2012年，入选教育部“中德职教汽车机电合作项目”试点院校；2014年获国家高等职业教育数字媒体专业群教学资源库立项；2015年，深圳市人力资源与社会保障局同意批准我校设立博士后创新实践基地；2016年，学校国家骨干校建设项目以“优秀”等级通过国家验收、获广东省“一流校”建设立项、学校“2188创客空间”被国家科学技术部认定为国家级众创空间，2016年学校又成功召开了第二次党代会，进一步确立了“全力打造有特色国际化一流职业院校”的奋斗目标。//青春深信成新锐，勇向潮头唱大风。学校将继续开拓奋进，勇于不断创新，努力把学校打造成有特色国际化一流职业院校。 | AB10: 学校原名为深圳信息职业技术学院，于2002年4月由深圳教育学院、深圳市工业学校、深圳市财经学校三所学校合并组建；2011年9月，学校从深圳市罗湖区迁至深圳市龙岗区。2012年，学校入选教育部“中德职教汽车机电合作项目”试点院校。2021年，学校获批设立广东省博士工作站。2025年6月，教育部发函广东省，同意以深圳信息职业技术学院为基础设立深圳信息职业技术大学，同时撤销深圳信息职业技术学院的建制。2026年1月，深圳信息职业技术大学正式成立。 | AC10: http://www.sziit.com.cn/ | AD10: http://zhaob.sziit.edu.cn/index.htm | AE10: 075589226360、075589226361 | AF10: 深圳市龙岗区龙翔大道2188号 | AG10: https://www.720yun.com/t/d4528mpguus | AH10: 184 | AI10: https://baike.baidu.com/item/%E6%B7%B1%E5%9C%B3%E4%BF%A1%E6%81%AF%E8%81%8C%E4%B8%9A%E6%8A%80%E6%9C%AF%E5%AD%A6%E9%99%A2 | AJ10: https://gaokao.chsi.com.cn/zsgs/zhangcheng/listZszc//schId/1429.dhtml | AK10: /
A11: 6 | B11: =C11 -> 6 | C11: 6 | D11: 依据学考 | E11: 12957 | F11: 深圳信息职业技术大学 | G11: 601 | H11: 276 | I11: 28 | J11: 276 | K11: 28 | L11: 395 | M11: 400 | N11: 6289 | O11: 9192 | P11: =IFERROR(AVERAGE(L11:M11),"/") -> 397.5 | Q11: =IFERROR(AVERAGE(N11:O11),"/") -> 7740.5 | R11: 广东省 | S11: 深圳市 | T11: 广东省 | U11: 职业本科 | V11: 广东省 | W11: 公办 | X11: 一线城市 | Y11: 双高计划/高水平学校建设单位/国家级骨干/现代学徒制试点学院 | Z11: 第二类高水平学校B档骨干高职现代学徒 | AA11: 深圳信息职业技术学院创办于2002年4月，是经广东省人民政府批准、教育部备案，由深圳市人民政府举办的公办全日制高等院校。//学校现为国家示范（骨干）高职院校、国家示范性软件职业技术学院、教育部“中德职教汽车机电合作项目”试点院校，现拥有3个国家级高等职业教育专业教学资源库（含1个备选项目）。学校拥有现代化、生态型、信息化的校园，占地92.6万平方米（1389亩），建筑面积58.86万平方米。学校现有教学科研仪器设备总值为36786.36万元，图书馆藏书131.33万册。//学校对接深圳支柱产业，打造信息技术特色，共设软件学院、电子与通信学院、计算机学院、数字媒体学院、智能制造与装备学院、交通与环境学院、管理学院、财经学院、应用外语学院、中德学院、马克思主义学院、继续教育学院、创新创业学院、创新教育研究院、公共课教学部、体育部、信息技术研究所等14院2部1所；开设信息类为主的专业44个。现有国家骨干校重点建设专业4个，国家高等职业学校提升专业服务产业发展能力建设专业2个，全国职业院校示范专业点2个，国家高等职业教育教学资源库建设项目3个（含1个备选项目），广东省示范性专业4个，省级重点建设专业6个，省级品牌专业11个；国家级精品资源共享课7门、省级精品资源共享课（含精品在线开放课）38门、省级思想政治理论优质建设课程2门。//学校现有教职工796人，在590位专任教师中，副高及以上职称教师301人，其中，博士、博士后275人，“双师素质”教师九成。目前，学校拥有国家级教学团队1个，获国家级教学名师奖1人，获全国五一劳动奖章1人，国家万人计划教学名师1名，广东省教学名师奖3人，广东省“特支计划”教学名师3人，省级教学团队7个，南粤优秀教师7人，广东省“千百十人才培养工程”省级培养对象6人，广东省“珠江学者”特聘教授4人，深圳市“鹏城学者”特聘教授3人，深圳市政府特殊津贴1人，黄炎培职业教育杰出教师奖1人，深圳市高层次专业人才地方级领军人才9名，后备级领军人才21人，博士后创新实践基地在站博士后3人。//学校坚持科研引领、教研创新、突出应用、服务社会。已主持国家自然科学基金等国家级项目26项、省市级科研项目517项，教研课题国家级6项、省市级49项，深圳市首批教育科研专家工作室1个。获得国家级高等学校教学成果一等奖1项、二等奖2项，省级教学成果一等奖6项、二等奖4项，广东省科学技术二等奖2项、三等奖2项，国家教师科研基金“十一五”规划重点课题科研成果一等奖1项，深圳市科技进步奖2项，深圳市科技创新奖2项，深圳市科学技术奖自然科学奖1项，深圳市哲学社会科学优秀成果奖7项，中国人工智能学会进步奖二等奖；拥有发明专利62项，实用新型专利203项，外观设计专利8项。//学校坚持校企合作办学，积极推进产教融合协同育人，创新合作办学机制，探索校企合作模式，在校内构建了“三会两办”的办学机制，并打造了“学院+行业企业”的校企合作模式。学校用2万平米实训场地，引企入校，合作共建实践教学基地、科技创新平台等，基地目前建有2个省级创新平台、1个先进土木研究中心、1个智能制造实训中心、5个校级协同创新中心等创新载体。学校有国家级高等职业教育实训基地2个，省级高等职业教育实训基地11个，省级公共实训中心1个，省级大学生校外实践教学基地12个，深圳市高职教育校外公共实训基地33个。//学校建构高素质高技能人才培养机制，不断提升高就业率、高满意度办学效益。现有全日制在校生15468人，学校坚持产教融合、校企合作、因材施教、特色发展。近三年，学生参加专业技能竞赛共获国家级奖项137个，省级二等奖以上315个。毕业生“下得去、留得住、用得上、干得好”，毕业生总体就业率均在98%以上。毕业生被华为、腾讯、深圳地铁、中国联通等著名企业录用，产生了被《华尔街日报》报道为“中国最年轻90后千万富豪”丁仕源、拥有8家公司的速运邦邦CEO陈家良等创业典型。//学校积极引进国际先进教学资源，不断形成国际化办学特色。2012年，学校成为教育部“中德职教汽车机电合作项目”试点院校；2013年11月学校与西双版纳职业技术学院正式签署合作协议共建“深圳信息/西双版纳国际留学生基地”/并揭牌；2016年9月，由深圳市教育局和德国巴伐利亚州文教部推动，我校与德国巴伐利亚州帕绍技术学校、兰茨胡特应用技术大学合作创办中德学院；2018年5月，学校与芬兰于韦斯屈莱应用科技大学签订战略合作协议全面启动两校战略合作项目；此外，学校还与加拿大谢尔丹理工学院、韩国京畿大学、台湾地区朝阳科技大学、树德科技大学、龙华科技大学、台北城市科技大学、亚太创意技术学院等26所高校开展了师生交流、合作科研等项目。//学校跨越发展，已跻身全国高职院校“第一方阵”。2004年，学校成为“国家示范性软件职业技术学院”建设院校；2007年，以优异成绩通过教育部人才培养工作水平评估；2010年，成为国家骨干高职院校建设单位；2011年，获国家高等职业教育网络技术专业共享型教学资源库建设立项；2012年，入选教育部“中德职教汽车机电合作项目”试点院校；2014年获国家高等职业教育数字媒体专业群教学资源库立项；2015年，深圳市人力资源与社会保障局同意批准我校设立博士后创新实践基地；2016年，学校国家骨干校建设项目以“优秀”等级通过国家验收、获广东省“一流校”建设立项、学校“2188创客空间”被国家科学技术部认定为国家级众创空间，2016年学校又成功召开了第二次党代会，进一步确立了“全力打造有特色国际化一流职业院校”的奋斗目标。//青春深信成新锐，勇向潮头唱大风。学校将继续开拓奋进，勇于不断创新，努力把学校打造成有特色国际化一流职业院校。 | AB11: 学校原名为深圳信息职业技术学院，于2002年4月由深圳教育学院、深圳市工业学校、深圳市财经学校三所学校合并组建；2011年9月，学校从深圳市罗湖区迁至深圳市龙岗区。2012年，学校入选教育部“中德职教汽车机电合作项目”试点院校。2021年，学校获批设立广东省博士工作站。2025年6月，教育部发函广东省，同意以深圳信息职业技术学院为基础设立深圳信息职业技术大学，同时撤销深圳信息职业技术学院的建制。2026年1月，深圳信息职业技术大学正式成立。 | AC11: http://www.sziit.com.cn/ | AD11: http://zhaob.sziit.edu.cn/index.htm | AE11: 075589226360、075589226361 | AF11: 深圳市龙岗区龙翔大道2188号 | AG11: https://www.720yun.com/t/d4528mpguus | AH11: 184 | AI11: https://baike.baidu.com/item/%E6%B7%B1%E5%9C%B3%E4%BF%A1%E6%81%AF%E8%81%8C%E4%B8%9A%E6%8A%80%E6%9C%AF%E5%AD%A6%E9%99%A2 | AJ11: https://gaokao.chsi.com.cn/zsgs/zhangcheng/listZszc//schId/1429.dhtml | AK11: /
A12: 7 | B12: =C12 -> 0 | D12: 依据学考 | E12: 11113 | F12: 深圳职业技术大学 | G12: 603 | H12: 703 | I12: 851 | J12: 703 | K12: 851 | L12: 390 | M12: 401 | N12: 9367 | O12: 7328 | P12: =IFERROR(AVERAGE(L12:M12),"/") -> 395.5 | Q12: =IFERROR(AVERAGE(N12:O12),"/") -> 8347.5 | R12: 广东省 | S12: 深圳市 | T12: 广东省 | U12: 职业本科 | V12: 广东省 | W12: 公办 | X12: 一线城市 | Y12: 省属/双高计划/高水平学校建设单位/国家级示范 | Z12: 第一类高水平学校A档示范高职 | AA12: 深圳职业技术学院1993年创建，是国内最早独立举办高等职业技术教育的院校之一。建校以来，深职院人艰苦创业，开拓进取，不断创新教育教学理念、办学体制机制和人才培养模式，创造了中国高职教育的多个第一。学校依托珠三角产业发展，秉承深圳特区改革创新精神，坚持把立德树人作为学校教育的根本任务，立足于职业教育产教融合的办学特色，各项事业取得骄人成绩，被誉为中国高职教育的“一面旗帜”。为紧密契合“中国制造2025”等国家重大战略和深圳创新驱动发展战略，学校在2016年底召开的第三次党代会工作报告中提出“三个服务、五个定位、一个率先”的战略发展目标，始终坚持为党和国家服务、为深圳经济社会发展服务、为学生健康成长成才服务，努力成为职业教育创新发展的先行者、复合式创新型高素质技术技能人才的摇篮、企业家的摇篮、深圳中小微企业技术研发中心、深圳市民终身教育学校与中国职业教育师资培训重要基地，率先建成中国特色、世界一流职业院校，为世界职业教育发展贡献“深圳模式”。////学校现有留仙洞、西丽湖、官龙山、华侨城、凤凰山五个校区，校园总面积212万平方米，学校产权校舍建筑面积57.34万平方米，其中教室10.75万平方米，图书馆5万平方米，体育馆3.34万平方米，实训实习场所10.14万平方米。现有固定资产总值23.66亿元，其中教学仪器设备总值9.58亿元,教学用计算机14525台。图书馆藏有纸质图书261.2万册，电子图书130万册，电子期刊60.54万册，中外文数据库46个，音视频16.07万小时。////全校现有教职员工2380人，其中专任教师1243人，正高217人，副高657人，博士408人，享受国务院特殊津贴专家2名，珠江学者5人、海外高层次人才25人、国家“万人计划”教学名师1人、国家级教学名师3人、省级教学名师8人、国家特支计划教师1人、广东特支计划教学名师4人。学校拥有教育部首批黄大年式教师团队1个；引进美国霍夫曼诺奖团队等一批重量级团队，成立霍夫曼先进材料研究院、智能科学与工程研究院、智能制造研究院、新时代中国职业教育研究院、社会与经济发展研究院等高端平台，为珠三角产业发展提供有力支撑。////学校设有电子与通信工程学院等17个二级学院和体育部、工业中心、国际教育部等教学单位，招生专业80个。全校普通全日制在校生22750人，其中港澳台留学生79人，四年制高职生284人，应用型本科生292人，外国留学生127人。自办专科教育在校生3536人。国家级教学成果奖14项，国家职业教育专业教学资源库3项，国家重点支持建设示范专业12个，中央财政支持实训基地9个，国家级精品教材12部，国家精品课程53门，国家级精品资源共享课43门。////学校一直把人才培养作为中心工作，以培养适应智能时代需要的复合式创新型高素质技术技能人才为目标，更新教育教学理念，探索实施以学生学习成效为导向的OBE（Outcome/Based/Education）人才培养模式改革，深入推进产教融合、职普融合、理实融合、技术与文化融合、教育与生活融合、现代信息技术与教学融合等“六个融合”，提升学生的就业能力、职业生涯拓展能力和幸福生活创造能力。瞄准未来社会和经济发展，紧贴深圳四大支柱产业和新兴产业布局专业，打造品牌专业，与华为、ARM、阿里巴巴、平安、比亚迪、裕同、天健等一流企业紧密合作，共建华为信息与网络技术学院、ARM智能硬件学院、阿里巴巴数字贸易学院、平安金融科技学院、比亚迪应用技术学院、裕同数字图文学院、天健建工学院等7所特色产业学院，校企共同制定专业标准、共同开发课程、共建师资团队、共同培养技术技能人才，在服务一流企业中成就自身一流。开设专业文化课程，大力培育工匠精神，厚植工匠文化，全面推进职业院校文化育人。学校已累计培养11万余名全日制专科毕业生，毕业生初次就业率始终保持在96%以上，多项人才培养质量指标位居全国高职院校前列，深受用人单位欢迎。其中，238人次获CCIE证书，13人获RHCA证书，57人获OCM证书，163人获HCIE证书，13人获RHCE证书。////学校探索实施创新创业教育改革，以“五维一体”的创新创业教育理念（重心在“教育”、路径在“分层”、目标在“万众”、核心在“创新”、关键在“实践”）为引领，打造深圳中小微企业技术研发中心、全球技术技能人才创新创业教育中心，以及创新型人才和企业家培养的成长摇篮。通过系统设计、科学构建，协同推进从启蒙教育、预科教育、专门教育到指导创办企业的进阶式创业人才培养体系，搭建“四会两赛三联盟”双创交流平台和“创新型社团—创客中心—学生创意创业园”双创实践平台，逐步完善跨界融合、产品试制、创业孵化、创业投资的双创服务体系，取得良好的社会效益。近年来获评首批全国创新创业典型经验高校、全国深化创新创业教育改革示范高校、广东省大众创业万众创新示范基地、深圳首批十大创新创业基地等。近四届毕业生毕业一年内自主创业比例达到5%，毕业三年后创业比例12.7%。////学校坚持以“产学研用”一体化的科研导向，重视技术转移和科技成果转化。近年来，学校不断深化科研体制机制改革，大力加强与政府职能部门以及行业企业合作，组建成立了应用技术研发院、文化创意产品研发院、经济与社会发展研究院等三大综合性研发平台，建成43个市区级以上科研平台,抢抓产业发展新机遇，服务地方经济社会和中小企业发展。全校累计承担各级各类科研课题5196项，其中国家级项目84项,年度新增国家自然科学基金项目10项。科研经费到账总经费达到8.06亿元，其中技术转移（横向科研）项目到账经费2.98亿元；出版各类学术专著226部、编著、译著和作品集共199部，61项科研成果获部、省、市级奖励；获国家专利授权1726项，软件著作权登记1136件，发明专利345项。主导或参与制定国际、国家、行业标准74项。////学校重视社会服务，发挥品牌优势，致力于推动现代职业教育培训体系和学习型社会建设。做好高水平师资培训，打造世界级的职业教育培训中心；做好职业培训、职业技能鉴定及职业资格认证工作，服务好地方经济发展需要；联合社区街道组建社区学院、特色学院，开展针对社区居民的健康、养老、旅游等培训项目，服务好地方社会发展需要；以办学理念和教学模式输出为主要内容，构建“理念—教学—师资—管理”四位一体的精准帮扶体系，服务好对口支援地区和院校的发展。全年重点对口帮扶11所职业院校，累计对口支援西藏、新疆、贵州等地11个省、自治区的200余所职业院校。全年举办33个全国高职高专师资培训班，累计为全国680余所职业院校培训骨干教师1.2万人次，连续5年名列全国第一。年均开展各类培训、职业技能鉴定与资格认证12万人次。组建西丽社区学院、大鹏旅游学院等社区学院，与社区共同培养技能人才，打造开放办学、产教融合的“职教特区”；选派核心团队建设管理吉安职业技术学院，开创了特区与老区携手共同发展职业教育的典范。////学校紧扣国家发展战略，加快国际化办学步伐，充分利用区域与自身优势，深化国际教育交流与合作。建校以来，已累计与32个国家和地区的162所高校和教育机构建立了友好合作关系，包括英国、德国、法国、美国等发达国家以及新西兰、马来西亚、保加利亚、土耳其、波兰、匈牙利、缅甸、老挝等14个“一带一路”沿线国家。双方在学生交换、课程合作、科研合作、短期研修等领域开展了全方位、多层次、形式多样的教师和学生国际交流活动，取得了丰硕的成果。近年来，我校年均接待境外来访师生及外宾108批次，658人次；我校赴境外参加国际交流的师生52批次，276人次。开办了国际商务（中澳）、金融管理（中澳）、物流管理（中美）和软件技术（中美）4个中外合作办学专业；与香港专业教育学院黄克竞分校合办电气服务工程高级文凭合作课程，毕业生获得深港两地毕业资格，并成为首批获得招收海外留学生资质的高职院校和首个获批面向港澳台自主招生的高职院校。学校还联合中兴、招商港口等一批世界一流企业“走出去”，服务国家“一带一路”倡议。在马来西亚马六甲应用技术大学设立职业教育与培训中心，推动马来西亚全国各类职业院校全面对接深职院标准。依托在保加利亚成立的职业教育与培训中心，输出学校专业标准。应邀为柬埔寨、蒙古等国家职业教育代表团举行专题培训班，输出职业教育经验。加强与职业教育国际组织的合作，成为联合国教科文组织国际职教全球联系中心之一，获批成立联合国教科文组织职业教育计划亚非研究与培训中心。在提高学校国际知名度与影响力的同时，为推动中国职业教育与语言文化走出去做出了积极贡献。////学校办学成绩显著。2001年首家通过国家示范性高职院校实践教学基地优秀评估，2009年通过国家示范性高等职业院校建设项目验收，成为我国高等职业教育领域首批国家级示范校。近年来，学校先后荣获“全国文明单位”、“全国职业教育先进单位”、“全国一流高职院校建设单位”、“首批全国创新创业典型经验高校”、“全国高校毕业生就业工作先进集体”、“中国十大最具就业力高职院校”、“全国毕业生就业工作典型经验高校”、“全国职业院校就业竞争力示范校”、“中国十大创新型高职院校”、“黄炎培优秀学校奖”、“全国高校实践育人创新创业基地”“广东省文明单位”、“广东省职业技术教育工作先进集体”、“广东省首批大学生创新创业教育示范学校”、“广东省一流高职院校建设单位”“深圳市创新创业基地”等荣誉称号。 | AB12: 深圳职业技术大学于1993年创建，前身为深圳职业技术学院，是中国国内最早独立举办高等职业技术教育的院校之一。2000年、2004年原深圳市职业技术学校、深圳市卫生学校分别并入深圳职业技术学院。2006年深圳职业技术学院被确定为“国家示范性高等职业院校建设计划”首批立项建设院校，2009年学校顺利通过验收成为首批国家示范性高等职业院校。2023年6月，教育部发文同意以深圳职业技术学院为基础整合资源设立深圳职业技术大学，同时撤销深圳职业技术学院的建制。 | AC12: http://www.szpt.edu.cn/ | AD12: https://zhaosheng.szpt.edu.cn/ | AE12: 0755/26731715、26731216 | AF12: 深圳市南山区西丽街道留仙大道7098号 | AG12: https://www.720yun.com/t/d8vksm7e0d9 | AH12: 158 | AI12: https://baike.baidu.com/item/%E6%B7%B1%E5%9C%B3%E8%81%8C%E4%B8%9A%E6%8A%80%E6%9C%AF%E5%A4%A7%E5%AD%A6 | AJ12: https://gaokao.chsi.com.cn/zsgs/zhangcheng/listZszc//schId/734.dhtml | AK12: /
A13: 8 | B13: =C13 -> 0 | D13: 依据学考 | E13: 11113 | F13: 深圳职业技术大学 | G13: 604 | H13: 282 | I13: 343 | J13: 282 | K13: 343 | L13: 390 | M13: 401 | N13: 9890 | O13: 7402 | P13: =IFERROR(AVERAGE(L13:M13),"/") -> 395.5 | Q13: =IFERROR(AVERAGE(N13:O13),"/") -> 8646 | R13: 广东省 | S13: 深圳市 | T13: 广东省 | U13: 职业本科 | V13: 广东省 | W13: 公办 | X13: 一线城市 | Y13: 省属/双高计划/高水平学校建设单位/国家级示范 | Z13: 第一类高水平学校A档示范高职 | AA13: 深圳职业技术学院1993年创建，是国内最早独立举办高等职业技术教育的院校之一。建校以来，深职院人艰苦创业，开拓进取，不断创新教育教学理念、办学体制机制和人才培养模式，创造了中国高职教育的多个第一。学校依托珠三角产业发展，秉承深圳特区改革创新精神，坚持把立德树人作为学校教育的根本任务，立足于职业教育产教融合的办学特色，各项事业取得骄人成绩，被誉为中国高职教育的“一面旗帜”。为紧密契合“中国制造2025”等国家重大战略和深圳创新驱动发展战略，学校在2016年底召开的第三次党代会工作报告中提出“三个服务、五个定位、一个率先”的战略发展目标，始终坚持为党和国家服务、为深圳经济社会发展服务、为学生健康成长成才服务，努力成为职业教育创新发展的先行者、复合式创新型高素质技术技能人才的摇篮、企业家的摇篮、深圳中小微企业技术研发中心、深圳市民终身教育学校与中国职业教育师资培训重要基地，率先建成中国特色、世界一流职业院校，为世界职业教育发展贡献“深圳模式”。////学校现有留仙洞、西丽湖、官龙山、华侨城、凤凰山五个校区，校园总面积212万平方米，学校产权校舍建筑面积57.34万平方米，其中教室10.75万平方米，图书馆5万平方米，体育馆3.34万平方米，实训实习场所10.14万平方米。现有固定资产总值23.66亿元，其中教学仪器设备总值9.58亿元,教学用计算机14525台。图书馆藏有纸质图书261.2万册，电子图书130万册，电子期刊60.54万册，中外文数据库46个，音视频16.07万小时。////全校现有教职员工2380人，其中专任教师1243人，正高217人，副高657人，博士408人，享受国务院特殊津贴专家2名，珠江学者5人、海外高层次人才25人、国家“万人计划”教学名师1人、国家级教学名师3人、省级教学名师8人、国家特支计划教师1人、广东特支计划教学名师4人。学校拥有教育部首批黄大年式教师团队1个；引进美国霍夫曼诺奖团队等一批重量级团队，成立霍夫曼先进材料研究院、智能科学与工程研究院、智能制造研究院、新时代中国职业教育研究院、社会与经济发展研究院等高端平台，为珠三角产业发展提供有力支撑。////学校设有电子与通信工程学院等17个二级学院和体育部、工业中心、国际教育部等教学单位，招生专业80个。全校普通全日制在校生22750人，其中港澳台留学生79人，四年制高职生284人，应用型本科生292人，外国留学生127人。自办专科教育在校生3536人。国家级教学成果奖14项，国家职业教育专业教学资源库3项，国家重点支持建设示范专业12个，中央财政支持实训基地9个，国家级精品教材12部，国家精品课程53门，国家级精品资源共享课43门。////学校一直把人才培养作为中心工作，以培养适应智能时代需要的复合式创新型高素质技术技能人才为目标，更新教育教学理念，探索实施以学生学习成效为导向的OBE（Outcome/Based/Education）人才培养模式改革，深入推进产教融合、职普融合、理实融合、技术与文化融合、教育与生活融合、现代信息技术与教学融合等“六个融合”，提升学生的就业能力、职业生涯拓展能力和幸福生活创造能力。瞄准未来社会和经济发展，紧贴深圳四大支柱产业和新兴产业布局专业，打造品牌专业，与华为、ARM、阿里巴巴、平安、比亚迪、裕同、天健等一流企业紧密合作，共建华为信息与网络技术学院、ARM智能硬件学院、阿里巴巴数字贸易学院、平安金融科技学院、比亚迪应用技术学院、裕同数字图文学院、天健建工学院等7所特色产业学院，校企共同制定专业标准、共同开发课程、共建师资团队、共同培养技术技能人才，在服务一流企业中成就自身一流。开设专业文化课程，大力培育工匠精神，厚植工匠文化，全面推进职业院校文化育人。学校已累计培养11万余名全日制专科毕业生，毕业生初次就业率始终保持在96%以上，多项人才培养质量指标位居全国高职院校前列，深受用人单位欢迎。其中，238人次获CCIE证书，13人获RHCA证书，57人获OCM证书，163人获HCIE证书，13人获RHCE证书。////学校探索实施创新创业教育改革，以“五维一体”的创新创业教育理念（重心在“教育”、路径在“分层”、目标在“万众”、核心在“创新”、关键在“实践”）为引领，打造深圳中小微企业技术研发中心、全球技术技能人才创新创业教育中心，以及创新型人才和企业家培养的成长摇篮。通过系统设计、科学构建，协同推进从启蒙教育、预科教育、专门教育到指导创办企业的进阶式创业人才培养体系，搭建“四会两赛三联盟”双创交流平台和“创新型社团—创客中心—学生创意创业园”双创实践平台，逐步完善跨界融合、产品试制、创业孵化、创业投资的双创服务体系，取得良好的社会效益。近年来获评首批全国创新创业典型经验高校、全国深化创新创业教育改革示范高校、广东省大众创业万众创新示范基地、深圳首批十大创新创业基地等。近四届毕业生毕业一年内自主创业比例达到5%，毕业三年后创业比例12.7%。////学校坚持以“产学研用”一体化的科研导向，重视技术转移和科技成果转化。近年来，学校不断深化科研体制机制改革，大力加强与政府职能部门以及行业企业合作，组建成立了应用技术研发院、文化创意产品研发院、经济与社会发展研究院等三大综合性研发平台，建成43个市区级以上科研平台,抢抓产业发展新机遇，服务地方经济社会和中小企业发展。全校累计承担各级各类科研课题5196项，其中国家级项目84项,年度新增国家自然科学基金项目10项。科研经费到账总经费达到8.06亿元，其中技术转移（横向科研）项目到账经费2.98亿元；出版各类学术专著226部、编著、译著和作品集共199部，61项科研成果获部、省、市级奖励；获国家专利授权1726项，软件著作权登记1136件，发明专利345项。主导或参与制定国际、国家、行业标准74项。////学校重视社会服务，发挥品牌优势，致力于推动现代职业教育培训体系和学习型社会建设。做好高水平师资培训，打造世界级的职业教育培训中心；做好职业培训、职业技能鉴定及职业资格认证工作，服务好地方经济发展需要；联合社区街道组建社区学院、特色学院，开展针对社区居民的健康、养老、旅游等培训项目，服务好地方社会发展需要；以办学理念和教学模式输出为主要内容，构建“理念—教学—师资—管理”四位一体的精准帮扶体系，服务好对口支援地区和院校的发展。全年重点对口帮扶11所职业院校，累计对口支援西藏、新疆、贵州等地11个省、自治区的200余所职业院校。全年举办33个全国高职高专师资培训班，累计为全国680余所职业院校培训骨干教师1.2万人次，连续5年名列全国第一。年均开展各类培训、职业技能鉴定与资格认证12万人次。组建西丽社区学院、大鹏旅游学院等社区学院，与社区共同培养技能人才，打造开放办学、产教融合的“职教特区”；选派核心团队建设管理吉安职业技术学院，开创了特区与老区携手共同发展职业教育的典范。////学校紧扣国家发展战略，加快国际化办学步伐，充分利用区域与自身优势，深化国际教育交流与合作。建校以来，已累计与32个国家和地区的162所高校和教育机构建立了友好合作关系，包括英国、德国、法国、美国等发达国家以及新西兰、马来西亚、保加利亚、土耳其、波兰、匈牙利、缅甸、老挝等14个“一带一路”沿线国家。双方在学生交换、课程合作、科研合作、短期研修等领域开展了全方位、多层次、形式多样的教师和学生国际交流活动，取得了丰硕的成果。近年来，我校年均接待境外来访师生及外宾108批次，658人次；我校赴境外参加国际交流的师生52批次，276人次。开办了国际商务（中澳）、金融管理（中澳）、物流管理（中美）和软件技术（中美）4个中外合作办学专业；与香港专业教育学院黄克竞分校合办电气服务工程高级文凭合作课程，毕业生获得深港两地毕业资格，并成为首批获得招收海外留学生资质的高职院校和首个获批面向港澳台自主招生的高职院校。学校还联合中兴、招商港口等一批世界一流企业“走出去”，服务国家“一带一路”倡议。在马来西亚马六甲应用技术大学设立职业教育与培训中心，推动马来西亚全国各类职业院校全面对接深职院标准。依托在保加利亚成立的职业教育与培训中心，输出学校专业标准。应邀为柬埔寨、蒙古等国家职业教育代表团举行专题培训班，输出职业教育经验。加强与职业教育国际组织的合作，成为联合国教科文组织国际职教全球联系中心之一，获批成立联合国教科文组织职业教育计划亚非研究与培训中心。在提高学校国际知名度与影响力的同时，为推动中国职业教育与语言文化走出去做出了积极贡献。////学校办学成绩显著。2001年首家通过国家示范性高职院校实践教学基地优秀评估，2009年通过国家示范性高等职业院校建设项目验收，成为我国高等职业教育领域首批国家级示范校。近年来，学校先后荣获“全国文明单位”、“全国职业教育先进单位”、“全国一流高职院校建设单位”、“首批全国创新创业典型经验高校”、“全国高校毕业生就业工作先进集体”、“中国十大最具就业力高职院校”、“全国毕业生就业工作典型经验高校”、“全国职业院校就业竞争力示范校”、“中国十大创新型高职院校”、“黄炎培优秀学校奖”、“全国高校实践育人创新创业基地”“广东省文明单位”、“广东省职业技术教育工作先进集体”、“广东省首批大学生创新创业教育示范学校”、“广东省一流高职院校建设单位”“深圳市创新创业基地”等荣誉称号。 | AB13: 深圳职业技术大学于1993年创建，前身为深圳职业技术学院，是中国国内最早独立举办高等职业技术教育的院校之一。2000年、2004年原深圳市职业技术学校、深圳市卫生学校分别并入深圳职业技术学院。2006年深圳职业技术学院被确定为“国家示范性高等职业院校建设计划”首批立项建设院校，2009年学校顺利通过验收成为首批国家示范性高等职业院校。2023年6月，教育部发文同意以深圳职业技术学院为基础整合资源设立深圳职业技术大学，同时撤销深圳职业技术学院的建制。 | AC13: http://www.szpt.edu.cn/ | AD13: https://zhaosheng.szpt.edu.cn/ | AE13: 0755/26731715、26731216 | AF13: 深圳市南山区西丽街道留仙大道7098号 | AG13: https://www.720yun.com/t/d8vksm7e0d9 | AH13: 158 | AI13: https://baike.baidu.com/item/%E6%B7%B1%E5%9C%B3%E8%81%8C%E4%B8%9A%E6%8A%80%E6%9C%AF%E5%A4%A7%E5%AD%A6 | AJ13: https://gaokao.chsi.com.cn/zsgs/zhangcheng/listZszc//schId/734.dhtml | AK13: /
A14: 9 | B14: =C14 -> 0 | D14: 依据学考 | E14: 10833 | F14: 广东轻工职业技术大学 | G14: 603 | H14: 175 | I14: 120 | J14: 175 | K14: 120 | L14: 388 | M14: 400 | N14: 11128 | O14: 8363 | P14: =IFERROR(AVERAGE(L14:M14),"/") -> 394 | Q14: =IFERROR(AVERAGE(N14:O14),"/") -> 9745.5 | R14: 广东省 | S14: 广州市 | T14: 广东省 | U14: 职业本科 | V14: 广东省 | W14: 公办 | X14: 一线城市 | Y14: 省属/双高计划/高水平学校建设单位/国家级示范/现代学徒制试点学院 | Z14: 第二类高水平学校B档示范高职现代学徒 | AA14: 广东轻工职业技术学院创建于1933年，是省属唯一国家示范性高等职业院校，全国“双高”高职院校建设单位。前身是“广东省立第一职业学校”，至今已有86年职业教育历史，其中1959/1963年和1978/1983年两段时期，学校开办本科教育，现有全日制在校生21000余人。学校秉承“德能兼备，学以成之”的校训和“自强、敬业、求实、创新”的广轻精神，为珠三角地区乃至全国输送数万名高素质高技能应用型人才。////办学条件好////学校现有广州和南海两个校区，其中广州校区定位为“大文科校区”，文科、艺术类专业面向广州现代服务业；南海校区成为“大工科校区”，工科专业面向珠江西岸高端制造业，校园总面积1700多亩，校舍建筑面积43万多平方米，其中教学科研实训用房近20万平方米，图书馆3万多平方米，学生公寓近16万平方米。固定资产总值15.5亿元，教学仪器设备总值2亿多元，学校图书馆拥有藏书近160万册，电子图书200多万册。网络信息点数2万多个，音视频电子资源1万多小时，学校校园无线网络全覆盖。建有校内实践教学基地近350个、校外实训实习基地900多个。////办学成果优异////学校是广东省唯一拥有7个省级工程技术开发中心的高职院校，是同时拥有省级协同发展中心及协同育人平台的两所高职院校之一，是全国第一批教育信息化试点单位、教育部现代学徒制试点单位、全国高校思政研究会高职高专专业委员会副会长单位（广东省会长单位）、全国跨境电商专业人才培养示范校、全国群众体育先进单位、全国高职“一校一品”示范单位、全国社会实践工作优秀单位、广东省依法治校示范校单位、广东省创新创业示范校单位、广东省安全文明校园示范校单位、广东省示范职业教育集团、广东省集团化办学单位、国防教育特色学校。学校立项“国家标杆党支部”1个，并先后获得全国高等职业院校全国服务贡献50强（连续两年）、全国高等职业院校实习管理50强、全国高等职业院校教学资源50强、全国高等职业院校学生管理50强、全国高等职业院校教学管理50强、全国高等职业院校育人成效50强、亚太职业院校影响力50强、全国示范性高职院校影响力排行榜30强、全国普通高校竞赛评估（高职）20强，全国高职院校思政工作创新优秀示范案例50强。全国高职院校创新创业示范校50强。2019年中国高职高专院校综合竞争力排行榜第9名。////多功能文化食堂、智能垃圾分类系统等创新性后勤改革领先全国。////师资队伍结构合理，业务水平高////学校现有教职工1200余人，其中高级职称教师400余人（二级教授9人），珠江学者9/人，“双师”素质教师70/0余人；国务院特殊津贴专家2人，全国模范教师2人，国家级教学名师2人，国家级教学团队2个，国家“万人计划”教学名师1人，全国技术能手2人，全国青年岗位能手1人，全国高校思想政治理论课教师影响力人物2人，全国轻工行业先进工作者1人，中国轻工职业教育教学名师1人，全国辅导员年度人物1名，广东省高校“千百十工程”国家级培养对象2人，南粤优秀教师11人，南粤优秀教育工作者4人，广东省“特支计划”教学名师、广东省教学名师、专业领军人才等名师专家近70人。建立了一个由企业一线工作的技术人员、能工巧匠、高级经理人等组成的优质兼职教师资源库，兼职教师与专业专任教师数之比达到1:1以上。学校在广东省高职院校教师队伍建设考核中连续三年排名第一。2019年全国高职院校教师教学发展指数排前十名。////教学成果丰硕////学校设有机电技术学院、食品与生物技术学院、轻化工技术学院、信息技术学院、汽车技术学院、生态环境技术学院、艺术设计学院、财贸学院、管理学院、应用外语学院、创业学院、马克思主义学院和继续教育学院，三个协同教学中心（工业机器人协同教学中心、现代信息技术与新工科协同教学中心、应用外语协同教学中心），设20个专业群、69个招生专业。2016年11月，学校成立创业学院，面向全体学生进行创新创业通识教育，面向精英学生进行创新创业定制培养。学校已建成国家示范性专业4个、央财“支持高等职业学校提升专业服务产业发展能力”项目经费支持专业2个、省级示范性专业3个、省级重点（建设）专业13个、省级品牌专业建设项目13个，建有国家级教学资源库1个、国家级精品课程10门、国家级精品资源共享课程9门、全国高校职业发展与就业指导示范课程1门、国家教指委精品课程22门、省级精品课程21门、省级优质课程2门，立项省级精品开放课程4/5门，其中已验收3门，在建省级专业资源库2个。2009年以来，学校共获得国家级优秀教学成果二等奖10项，行业教指会特等奖2个，省级优秀教学成果一等奖9项，省级优秀教学成果二等奖5项。////职教特色明显，人才培养质量高////学校是教育部现代学徒制试点单位，已立项国家级现代学徒制试点项目3项，省级现代学徒制试点项目/9项。学校积极构建职业教育“立交桥”，全面实施“纵向延伸，横向拓展”协同育人模式，开展了“3+2”中高衔接、“2+2”和“4+0”高本联培、“3+2”高本衔接、工程硕士培养等多种形式的协同培养，其中本科专业共1/3个，搭建起“中/高/本/硕”现代职业教育体系框架。连续多年，录取人数和录取分数线均位居省内同类院校前茅，文理类、艺术类高考录取分数线均高于本科省控线。毕业生深受用人单位欢迎，母校的满意度和薪资水平高于全国示范校平均水平，初次就业率高于98%，用人单位满意度99%以上。学生在各级各类技能大赛中获奖数量与质量节节攀升。近三年来，共获得国家级奖项500多个、省部级奖项1000余个。////产教融合，社会服务能力强////学校构建并不断完善政校行企协同促进产教融合长效机制，围绕高水平专业群建设，打造“一群一院一联盟”，搭建了广东轻工职教集团、轻工行业应用技术协同创新发展中心、南海职业教育政校行企协同创新联盟、广东省工业互联网产教联盟、粤港澳数字创意产教联盟、粤港澳跨境电商产教联盟、广东酒店职业教育联盟、全国精准营养食品与果蔬加工产教联盟、国家中小微企业知识产权培训基地等产学研创新、科技研发与转化平台，与华为等世界500强知名企业合作成立了华为ICT学院、瀚蓝环境学院、白天鹅学院、雷诺钟表学院、许鸿飞国际文创学院等10个产业学院，实现校企精准对接，产教深度融合，精准育人。近五年，获国家级科技项目4项、省级36项；国家级、省级科技奖励13项；面向企业开展科技攻关项目200余项。申报专利近430项，授权近300项，专利申请量连续多年位列广州地区高校（含本科）前十名。////坚持对外合作，国际化办学水平高////学校积极广泛开展对外交流与合作，已与国（境）外多所高等院校建立了合作关系，在引进智力与优质教育资源、人才培养、合作办学、汉语言培训等方面开展了实质性的合作。累计已招收来自30多个国家的留学生4/00余名。2017年，学校牵头组建广东省“一带一路”职业教育联盟，输出广轻职教模式，服务“一带一路”沿线国家及地区，国际化办学呈现新气象。////构建终身教育体系，服务广东经济社会////依托“国家中小微企业知识产权培训（南海）基地”“广东轻工培训中心”“职教师资优质省级基地”“广东省专业技术人员继续教育基地”“广东省职业技能鉴定所”等国家级和省级平台，并设有专门和专业性培训机构30多个，面向社会、社区和产业、行业积极开展各级各类培训服务，年培训量超15万人天；与本科院校进行网络远程教育及自学考试合作，并在深圳、佛山、珠海、韶关等地设立12个校外专科继续教育教学点，学校各类学历继续教育在读人数4000余人。////“十三五”期间，学校将遵循“三大一强”院校治理理念，围绕“创新强校工程”及一流高职院校建设，努力把学校建成“国内一流、国际知名”国家优质高职院校，成为高职院校治理的标准与典范，成为高素质技术技能型人才培养的典范。 | AB14: 学校创建于1933年，原名广东省立第一职业学校，学校数易其名，先后更名为广东省立广州农工业职业学校、广东省立广州工业职业学校、广东省立广州高级工业职业学校、广东省广州高级工业技术学校、广东省轻工业学校、广东轻工业学院、广州轻工业学校等 ，1959～1963年和1978～1983年曾开办本科职业教育。 1999年，学校升格为广东轻工职业技术学院。 2020年，广东省轻工职业技术学校、广东省石油化工职业技术学校并入。 2024年6月，教育部正式同意在广东轻工职业技术学院的基础上设立广东轻工职业技术大学。 9月3日，广东轻工职业技术大学正式揭牌。 | AC14: http://www.gdqy.edu.cn/ | AD14: http://gdqyzs.jysd.com/ | AE14: 020/61230198 | AF14: 广州市新港西路152号 | AG14: / | AH14: 369 | AI14: https://baike.baidu.com/item/%E5%B9%BF%E4%B8%9C%E8%BD%BB%E5%B7%A5%E8%81%8C%E4%B8%9A%E6%8A%80%E6%9C%AF%E5%A4%A7%E5%AD%A6 | AJ14: https://gaokao.chsi.com.cn/zsgs/zhangcheng/listZszc//schId/620.dhtml | AK14: /
A15: 10 | B15: =C15 -> 0 | D15: 依据学考 | E15: 12957 | F15: 深圳信息职业技术大学 | G15: 606 | H15: 28 | I15: 73 | J15: 28 | K15: 73 | L15: 387 | M15: 398 | N15: 11959 | O15: 11459 | P15: =IFERROR(AVERAGE(L15:M15),"/") -> 392.5 | Q15: =IFERROR(AVERAGE(N15:O15),"/") -> 11709 | R15: 广东省 | S15: 深圳市 | T15: 广东省 | U15: 职业本科 | V15: 广东省 | W15: 公办 | X15: 一线城市 | Y15: 双高计划/高水平学校建设单位/国家级骨干/现代学徒制试点学院 | Z15: 第二类高水平学校B档骨干高职现代学徒 | AA15: 深圳信息职业技术学院创办于2002年4月，是经广东省人民政府批准、教育部备案，由深圳市人民政府举办的公办全日制高等院校。//学校现为国家示范（骨干）高职院校、国家示范性软件职业技术学院、教育部“中德职教汽车机电合作项目”试点院校，现拥有3个国家级高等职业教育专业教学资源库（含1个备选项目）。学校拥有现代化、生态型、信息化的校园，占地92.6万平方米（1389亩），建筑面积58.86万平方米。学校现有教学科研仪器设备总值为36786.36万元，图书馆藏书131.33万册。//学校对接深圳支柱产业，打造信息技术特色，共设软件学院、电子与通信学院、计算机学院、数字媒体学院、智能制造与装备学院、交通与环境学院、管理学院、财经学院、应用外语学院、中德学院、马克思主义学院、继续教育学院、创新创业学院、创新教育研究院、公共课教学部、体育部、信息技术研究所等14院2部1所；开设信息类为主的专业44个。现有国家骨干校重点建设专业4个，国家高等职业学校提升专业服务产业发展能力建设专业2个，全国职业院校示范专业点2个，国家高等职业教育教学资源库建设项目3个（含1个备选项目），广东省示范性专业4个，省级重点建设专业6个，省级品牌专业11个；国家级精品资源共享课7门、省级精品资源共享课（含精品在线开放课）38门、省级思想政治理论优质建设课程2门。//学校现有教职工796人，在590位专任教师中，副高及以上职称教师301人，其中，博士、博士后275人，“双师素质”教师九成。目前，学校拥有国家级教学团队1个，获国家级教学名师奖1人，获全国五一劳动奖章1人，国家万人计划教学名师1名，广东省教学名师奖3人，广东省“特支计划”教学名师3人，省级教学团队7个，南粤优秀教师7人，广东省“千百十人才培养工程”省级培养对象6人，广东省“珠江学者”特聘教授4人，深圳市“鹏城学者”特聘教授3人，深圳市政府特殊津贴1人，黄炎培职业教育杰出教师奖1人，深圳市高层次专业人才地方级领军人才9名，后备级领军人才21人，博士后创新实践基地在站博士后3人。//学校坚持科研引领、教研创新、突出应用、服务社会。已主持国家自然科学基金等国家级项目26项、省市级科研项目517项，教研课题国家级6项、省市级49项，深圳市首批教育科研专家工作室1个。获得国家级高等学校教学成果一等奖1项、二等奖2项，省级教学成果一等奖6项、二等奖4项，广东省科学技术二等奖2项、三等奖2项，国家教师科研基金“十一五”规划重点课题科研成果一等奖1项，深圳市科技进步奖2项，深圳市科技创新奖2项，深圳市科学技术奖自然科学奖1项，深圳市哲学社会科学优秀成果奖7项，中国人工智能学会进步奖二等奖；拥有发明专利62项，实用新型专利203项，外观设计专利8项。//学校坚持校企合作办学，积极推进产教融合协同育人，创新合作办学机制，探索校企合作模式，在校内构建了“三会两办”的办学机制，并打造了“学院+行业企业”的校企合作模式。学校用2万平米实训场地，引企入校，合作共建实践教学基地、科技创新平台等，基地目前建有2个省级创新平台、1个先进土木研究中心、1个智能制造实训中心、5个校级协同创新中心等创新载体。学校有国家级高等职业教育实训基地2个，省级高等职业教育实训基地11个，省级公共实训中心1个，省级大学生校外实践教学基地12个，深圳市高职教育校外公共实训基地33个。//学校建构高素质高技能人才培养机制，不断提升高就业率、高满意度办学效益。现有全日制在校生15468人，学校坚持产教融合、校企合作、因材施教、特色发展。近三年，学生参加专业技能竞赛共获国家级奖项137个，省级二等奖以上315个。毕业生“下得去、留得住、用得上、干得好”，毕业生总体就业率均在98%以上。毕业生被华为、腾讯、深圳地铁、中国联通等著名企业录用，产生了被《华尔街日报》报道为“中国最年轻90后千万富豪”丁仕源、拥有8家公司的速运邦邦CEO陈家良等创业典型。//学校积极引进国际先进教学资源，不断形成国际化办学特色。2012年，学校成为教育部“中德职教汽车机电合作项目”试点院校；2013年11月学校与西双版纳职业技术学院正式签署合作协议共建“深圳信息/西双版纳国际留学生基地”/并揭牌；2016年9月，由深圳市教育局和德国巴伐利亚州文教部推动，我校与德国巴伐利亚州帕绍技术学校、兰茨胡特应用技术大学合作创办中德学院；2018年5月，学校与芬兰于韦斯屈莱应用科技大学签订战略合作协议全面启动两校战略合作项目；此外，学校还与加拿大谢尔丹理工学院、韩国京畿大学、台湾地区朝阳科技大学、树德科技大学、龙华科技大学、台北城市科技大学、亚太创意技术学院等26所高校开展了师生交流、合作科研等项目。//学校跨越发展，已跻身全国高职院校“第一方阵”。2004年，学校成为“国家示范性软件职业技术学院”建设院校；2007年，以优异成绩通过教育部人才培养工作水平评估；2010年，成为国家骨干高职院校建设单位；2011年，获国家高等职业教育网络技术专业共享型教学资源库建设立项；2012年，入选教育部“中德职教汽车机电合作项目”试点院校；2014年获国家高等职业教育数字媒体专业群教学资源库立项；2015年，深圳市人力资源与社会保障局同意批准我校设立博士后创新实践基地；2016年，学校国家骨干校建设项目以“优秀”等级通过国家验收、获广东省“一流校”建设立项、学校“2188创客空间”被国家科学技术部认定为国家级众创空间，2016年学校又成功召开了第二次党代会，进一步确立了“全力打造有特色国际化一流职业院校”的奋斗目标。//青春深信成新锐，勇向潮头唱大风。学校将继续开拓奋进，勇于不断创新，努力把学校打造成有特色国际化一流职业院校。 | AB15: 学校原名为深圳信息职业技术学院，于2002年4月由深圳教育学院、深圳市工业学校、深圳市财经学校三所学校合并组建；2011年9月，学校从深圳市罗湖区迁至深圳市龙岗区。2012年，学校入选教育部“中德职教汽车机电合作项目”试点院校。2021年，学校获批设立广东省博士工作站。2025年6月，教育部发函广东省，同意以深圳信息职业技术学院为基础设立深圳信息职业技术大学，同时撤销深圳信息职业技术学院的建制。2026年1月，深圳信息职业技术大学正式成立。 | AC15: http://www.sziit.com.cn/ | AD15: http://zhaob.sziit.edu.cn/index.htm | AE15: 075589226360、075589226361 | AF15: 深圳市龙岗区龙翔大道2188号 | AG15: https://www.720yun.com/t/d4528mpguus | AH15: 184 | AI15: https://baike.baidu.com/item/%E6%B7%B1%E5%9C%B3%E4%BF%A1%E6%81%AF%E8%81%8C%E4%B8%9A%E6%8A%80%E6%9C%AF%E5%AD%A6%E9%99%A2 | AJ15: https://gaokao.chsi.com.cn/zsgs/zhangcheng/listZszc//schId/1429.dhtml | AK15: /
A16: 11 | B16: =C16 -> 0 | D16: 依据学考 | E16: 12957 | F16: 深圳信息职业技术大学 | G16: 605 | H16: 23 | I16: 25 | J16: 23 | K16: 25 | L16: 388 | M16: 397 | N16: 11740 | O16: 11856 | P16: =IFERROR(AVERAGE(L16:M16),"/") -> 392.5 | Q16: =IFERROR(AVERAGE(N16:O16),"/") -> 11798 | R16: 广东省 | S16: 深圳市 | T16: 广东省 | U16: 职业本科 | V16: 广东省 | W16: 公办 | X16: 一线城市 | Y16: 双高计划/高水平学校建设单位/国家级骨干/现代学徒制试点学院 | Z16: 第二类高水平学校B档骨干高职现代学徒 | AA16: 深圳信息职业技术学院创办于2002年4月，是经广东省人民政府批准、教育部备案，由深圳市人民政府举办的公办全日制高等院校。//学校现为国家示范（骨干）高职院校、国家示范性软件职业技术学院、教育部“中德职教汽车机电合作项目”试点院校，现拥有3个国家级高等职业教育专业教学资源库（含1个备选项目）。学校拥有现代化、生态型、信息化的校园，占地92.6万平方米（1389亩），建筑面积58.86万平方米。学校现有教学科研仪器设备总值为36786.36万元，图书馆藏书131.33万册。//学校对接深圳支柱产业，打造信息技术特色，共设软件学院、电子与通信学院、计算机学院、数字媒体学院、智能制造与装备学院、交通与环境学院、管理学院、财经学院、应用外语学院、中德学院、马克思主义学院、继续教育学院、创新创业学院、创新教育研究院、公共课教学部、体育部、信息技术研究所等14院2部1所；开设信息类为主的专业44个。现有国家骨干校重点建设专业4个，国家高等职业学校提升专业服务产业发展能力建设专业2个，全国职业院校示范专业点2个，国家高等职业教育教学资源库建设项目3个（含1个备选项目），广东省示范性专业4个，省级重点建设专业6个，省级品牌专业11个；国家级精品资源共享课7门、省级精品资源共享课（含精品在线开放课）38门、省级思想政治理论优质建设课程2门。//学校现有教职工796人，在590位专任教师中，副高及以上职称教师301人，其中，博士、博士后275人，“双师素质”教师九成。目前，学校拥有国家级教学团队1个，获国家级教学名师奖1人，获全国五一劳动奖章1人，国家万人计划教学名师1名，广东省教学名师奖3人，广东省“特支计划”教学名师3人，省级教学团队7个，南粤优秀教师7人，广东省“千百十人才培养工程”省级培养对象6人，广东省“珠江学者”特聘教授4人，深圳市“鹏城学者”特聘教授3人，深圳市政府特殊津贴1人，黄炎培职业教育杰出教师奖1人，深圳市高层次专业人才地方级领军人才9名，后备级领军人才21人，博士后创新实践基地在站博士后3人。//学校坚持科研引领、教研创新、突出应用、服务社会。已主持国家自然科学基金等国家级项目26项、省市级科研项目517项，教研课题国家级6项、省市级49项，深圳市首批教育科研专家工作室1个。获得国家级高等学校教学成果一等奖1项、二等奖2项，省级教学成果一等奖6项、二等奖4项，广东省科学技术二等奖2项、三等奖2项，国家教师科研基金“十一五”规划重点课题科研成果一等奖1项，深圳市科技进步奖2项，深圳市科技创新奖2项，深圳市科学技术奖自然科学奖1项，深圳市哲学社会科学优秀成果奖7项，中国人工智能学会进步奖二等奖；拥有发明专利62项，实用新型专利203项，外观设计专利8项。//学校坚持校企合作办学，积极推进产教融合协同育人，创新合作办学机制，探索校企合作模式，在校内构建了“三会两办”的办学机制，并打造了“学院+行业企业”的校企合作模式。学校用2万平米实训场地，引企入校，合作共建实践教学基地、科技创新平台等，基地目前建有2个省级创新平台、1个先进土木研究中心、1个智能制造实训中心、5个校级协同创新中心等创新载体。学校有国家级高等职业教育实训基地2个，省级高等职业教育实训基地11个，省级公共实训中心1个，省级大学生校外实践教学基地12个，深圳市高职教育校外公共实训基地33个。//学校建构高素质高技能人才培养机制，不断提升高就业率、高满意度办学效益。现有全日制在校生15468人，学校坚持产教融合、校企合作、因材施教、特色发展。近三年，学生参加专业技能竞赛共获国家级奖项137个，省级二等奖以上315个。毕业生“下得去、留得住、用得上、干得好”，毕业生总体就业率均在98%以上。毕业生被华为、腾讯、深圳地铁、中国联通等著名企业录用，产生了被《华尔街日报》报道为“中国最年轻90后千万富豪”丁仕源、拥有8家公司的速运邦邦CEO陈家良等创业典型。//学校积极引进国际先进教学资源，不断形成国际化办学特色。2012年，学校成为教育部“中德职教汽车机电合作项目”试点院校；2013年11月学校与西双版纳职业技术学院正式签署合作协议共建“深圳信息/西双版纳国际留学生基地”/并揭牌；2016年9月，由深圳市教育局和德国巴伐利亚州文教部推动，我校与德国巴伐利亚州帕绍技术学校、兰茨胡特应用技术大学合作创办中德学院；2018年5月，学校与芬兰于韦斯屈莱应用科技大学签订战略合作协议全面启动两校战略合作项目；此外，学校还与加拿大谢尔丹理工学院、韩国京畿大学、台湾地区朝阳科技大学、树德科技大学、龙华科技大学、台北城市科技大学、亚太创意技术学院等26所高校开展了师生交流、合作科研等项目。//学校跨越发展，已跻身全国高职院校“第一方阵”。2004年，学校成为“国家示范性软件职业技术学院”建设院校；2007年，以优异成绩通过教育部人才培养工作水平评估；2010年，成为国家骨干高职院校建设单位；2011年，获国家高等职业教育网络技术专业共享型教学资源库建设立项；2012年，入选教育部“中德职教汽车机电合作项目”试点院校；2014年获国家高等职业教育数字媒体专业群教学资源库立项；2015年，深圳市人力资源与社会保障局同意批准我校设立博士后创新实践基地；2016年，学校国家骨干校建设项目以“优秀”等级通过国家验收、获广东省“一流校”建设立项、学校“2188创客空间”被国家科学技术部认定为国家级众创空间，2016年学校又成功召开了第二次党代会，进一步确立了“全力打造有特色国际化一流职业院校”的奋斗目标。//青春深信成新锐，勇向潮头唱大风。学校将继续开拓奋进，勇于不断创新，努力把学校打造成有特色国际化一流职业院校。 | AB16: 学校原名为深圳信息职业技术学院，于2002年4月由深圳教育学院、深圳市工业学校、深圳市财经学校三所学校合并组建；2011年9月，学校从深圳市罗湖区迁至深圳市龙岗区。2012年，学校入选教育部“中德职教汽车机电合作项目”试点院校。2021年，学校获批设立广东省博士工作站。2025年6月，教育部发函广东省，同意以深圳信息职业技术学院为基础设立深圳信息职业技术大学，同时撤销深圳信息职业技术学院的建制。2026年1月，深圳信息职业技术大学正式成立。 | AC16: http://www.sziit.com.cn/ | AD16: http://zhaob.sziit.edu.cn/index.htm | AE16: 075589226360、075589226361 | AF16: 深圳市龙岗区龙翔大道2188号 | AG16: https://www.720yun.com/t/d4528mpguus | AH16: 184 | AI16: https://baike.baidu.com/item/%E6%B7%B1%E5%9C%B3%E4%BF%A1%E6%81%AF%E8%81%8C%E4%B8%9A%E6%8A%80%E6%9C%AF%E5%AD%A6%E9%99%A2 | AJ16: https://gaokao.chsi.com.cn/zsgs/zhangcheng/listZszc//schId/1429.dhtml | AK16: /
A17: 12 | B17: =C17 -> 0 | D17: 依据学考 | E17: 10833 | F17: 广东轻工职业技术大学 | G17: 609 | H17: 85 | I17: 120 | J17: 85 | K17: 120 | L17: 386 | M17: 398 | N17: 13427 | O17: 10558 | P17: =IFERROR(AVERAGE(L17:M17),"/") -> 392 | Q17: =IFERROR(AVERAGE(N17:O17),"/") -> 11992.5 | R17: 广东省 | S17: 广州市 | T17: 广东省 | U17: 职业本科 | V17: 广东省 | W17: 公办 | X17: 一线城市 | Y17: 省属/双高计划/高水平学校建设单位/国家级示范/现代学徒制试点学院 | Z17: 第二类高水平学校B档示范高职现代学徒 | AA17: 广东轻工职业技术学院创建于1933年，是省属唯一国家示范性高等职业院校，全国“双高”高职院校建设单位。前身是“广东省立第一职业学校”，至今已有86年职业教育历史，其中1959/1963年和1978/1983年两段时期，学校开办本科教育，现有全日制在校生21000余人。学校秉承“德能兼备，学以成之”的校训和“自强、敬业、求实、创新”的广轻精神，为珠三角地区乃至全国输送数万名高素质高技能应用型人才。////办学条件好////学校现有广州和南海两个校区，其中广州校区定位为“大文科校区”，文科、艺术类专业面向广州现代服务业；南海校区成为“大工科校区”，工科专业面向珠江西岸高端制造业，校园总面积1700多亩，校舍建筑面积43万多平方米，其中教学科研实训用房近20万平方米，图书馆3万多平方米，学生公寓近16万平方米。固定资产总值15.5亿元，教学仪器设备总值2亿多元，学校图书馆拥有藏书近160万册，电子图书200多万册。网络信息点数2万多个，音视频电子资源1万多小时，学校校园无线网络全覆盖。建有校内实践教学基地近350个、校外实训实习基地900多个。////办学成果优异////学校是广东省唯一拥有7个省级工程技术开发中心的高职院校，是同时拥有省级协同发展中心及协同育人平台的两所高职院校之一，是全国第一批教育信息化试点单位、教育部现代学徒制试点单位、全国高校思政研究会高职高专专业委员会副会长单位（广东省会长单位）、全国跨境电商专业人才培养示范校、全国群众体育先进单位、全国高职“一校一品”示范单位、全国社会实践工作优秀单位、广东省依法治校示范校单位、广东省创新创业示范校单位、广东省安全文明校园示范校单位、广东省示范职业教育集团、广东省集团化办学单位、国防教育特色学校。学校立项“国家标杆党支部”1个，并先后获得全国高等职业院校全国服务贡献50强（连续两年）、全国高等职业院校实习管理50强、全国高等职业院校教学资源50强、全国高等职业院校学生管理50强、全国高等职业院校教学管理50强、全国高等职业院校育人成效50强、亚太职业院校影响力50强、全国示范性高职院校影响力排行榜30强、全国普通高校竞赛评估（高职）20强，全国高职院校思政工作创新优秀示范案例50强。全国高职院校创新创业示范校50强。2019年中国高职高专院校综合竞争力排行榜第9名。////多功能文化食堂、智能垃圾分类系统等创新性后勤改革领先全国。////师资队伍结构合理，业务水平高////学校现有教职工1200余人，其中高级职称教师400余人（二级教授9人），珠江学者9/人，“双师”素质教师70/0余人；国务院特殊津贴专家2人，全国模范教师2人，国家级教学名师2人，国家级教学团队2个，国家“万人计划”教学名师1人，全国技术能手2人，全国青年岗位能手1人，全国高校思想政治理论课教师影响力人物2人，全国轻工行业先进工作者1人，中国轻工职业教育教学名师1人，全国辅导员年度人物1名，广东省高校“千百十工程”国家级培养对象2人，南粤优秀教师11人，南粤优秀教育工作者4人，广东省“特支计划”教学名师、广东省教学名师、专业领军人才等名师专家近70人。建立了一个由企业一线工作的技术人员、能工巧匠、高级经理人等组成的优质兼职教师资源库，兼职教师与专业专任教师数之比达到1:1以上。学校在广东省高职院校教师队伍建设考核中连续三年排名第一。2019年全国高职院校教师教学发展指数排前十名。////教学成果丰硕////学校设有机电技术学院、食品与生物技术学院、轻化工技术学院、信息技术学院、汽车技术学院、生态环境技术学院、艺术设计学院、财贸学院、管理学院、应用外语学院、创业学院、马克思主义学院和继续教育学院，三个协同教学中心（工业机器人协同教学中心、现代信息技术与新工科协同教学中心、应用外语协同教学中心），设20个专业群、69个招生专业。2016年11月，学校成立创业学院，面向全体学生进行创新创业通识教育，面向精英学生进行创新创业定制培养。学校已建成国家示范性专业4个、央财“支持高等职业学校提升专业服务产业发展能力”项目经费支持专业2个、省级示范性专业3个、省级重点（建设）专业13个、省级品牌专业建设项目13个，建有国家级教学资源库1个、国家级精品课程10门、国家级精品资源共享课程9门、全国高校职业发展与就业指导示范课程1门、国家教指委精品课程22门、省级精品课程21门、省级优质课程2门，立项省级精品开放课程4/5门，其中已验收3门，在建省级专业资源库2个。2009年以来，学校共获得国家级优秀教学成果二等奖10项，行业教指会特等奖2个，省级优秀教学成果一等奖9项，省级优秀教学成果二等奖5项。////职教特色明显，人才培养质量高////学校是教育部现代学徒制试点单位，已立项国家级现代学徒制试点项目3项，省级现代学徒制试点项目/9项。学校积极构建职业教育“立交桥”，全面实施“纵向延伸，横向拓展”协同育人模式，开展了“3+2”中高衔接、“2+2”和“4+0”高本联培、“3+2”高本衔接、工程硕士培养等多种形式的协同培养，其中本科专业共1/3个，搭建起“中/高/本/硕”现代职业教育体系框架。连续多年，录取人数和录取分数线均位居省内同类院校前茅，文理类、艺术类高考录取分数线均高于本科省控线。毕业生深受用人单位欢迎，母校的满意度和薪资水平高于全国示范校平均水平，初次就业率高于98%，用人单位满意度99%以上。学生在各级各类技能大赛中获奖数量与质量节节攀升。近三年来，共获得国家级奖项500多个、省部级奖项1000余个。////产教融合，社会服务能力强////学校构建并不断完善政校行企协同促进产教融合长效机制，围绕高水平专业群建设，打造“一群一院一联盟”，搭建了广东轻工职教集团、轻工行业应用技术协同创新发展中心、南海职业教育政校行企协同创新联盟、广东省工业互联网产教联盟、粤港澳数字创意产教联盟、粤港澳跨境电商产教联盟、广东酒店职业教育联盟、全国精准营养食品与果蔬加工产教联盟、国家中小微企业知识产权培训基地等产学研创新、科技研发与转化平台，与华为等世界500强知名企业合作成立了华为ICT学院、瀚蓝环境学院、白天鹅学院、雷诺钟表学院、许鸿飞国际文创学院等10个产业学院，实现校企精准对接，产教深度融合，精准育人。近五年，获国家级科技项目4项、省级36项；国家级、省级科技奖励13项；面向企业开展科技攻关项目200余项。申报专利近430项，授权近300项，专利申请量连续多年位列广州地区高校（含本科）前十名。////坚持对外合作，国际化办学水平高////学校积极广泛开展对外交流与合作，已与国（境）外多所高等院校建立了合作关系，在引进智力与优质教育资源、人才培养、合作办学、汉语言培训等方面开展了实质性的合作。累计已招收来自30多个国家的留学生4/00余名。2017年，学校牵头组建广东省“一带一路”职业教育联盟，输出广轻职教模式，服务“一带一路”沿线国家及地区，国际化办学呈现新气象。////构建终身教育体系，服务广东经济社会////依托“国家中小微企业知识产权培训（南海）基地”“广东轻工培训中心”“职教师资优质省级基地”“广东省专业技术人员继续教育基地”“广东省职业技能鉴定所”等国家级和省级平台，并设有专门和专业性培训机构30多个，面向社会、社区和产业、行业积极开展各级各类培训服务，年培训量超15万人天；与本科院校进行网络远程教育及自学考试合作，并在深圳、佛山、珠海、韶关等地设立12个校外专科继续教育教学点，学校各类学历继续教育在读人数4000余人。////“十三五”期间，学校将遵循“三大一强”院校治理理念，围绕“创新强校工程”及一流高职院校建设，努力把学校建成“国内一流、国际知名”国家优质高职院校，成为高职院校治理的标准与典范，成为高素质技术技能型人才培养的典范。 | AB17: 学校创建于1933年，原名广东省立第一职业学校，学校数易其名，先后更名为广东省立广州农工业职业学校、广东省立广州工业职业学校、广东省立广州高级工业职业学校、广东省广州高级工业技术学校、广东省轻工业学校、广东轻工业学院、广州轻工业学校等 ，1959～1963年和1978～1983年曾开办本科职业教育。 1999年，学校升格为广东轻工职业技术学院。 2020年，广东省轻工职业技术学校、广东省石油化工职业技术学校并入。 2024年6月，教育部正式同意在广东轻工职业技术学院的基础上设立广东轻工职业技术大学。 9月3日，广东轻工职业技术大学正式揭牌。 | AC17: http://www.gdqy.edu.cn/ | AD17: http://gdqyzs.jysd.com/ | AE17: 020/61230198 | AF17: 广州市新港西路152号 | AG17: / | AH17: 369 | AI17: https://baike.baidu.com/item/%E5%B9%BF%E4%B8%9C%E8%BD%BB%E5%B7%A5%E8%81%8C%E4%B8%9A%E6%8A%80%E6%9C%AF%E5%A4%A7%E5%AD%A6 | AJ17: https://gaokao.chsi.com.cn/zsgs/zhangcheng/listZszc//schId/620.dhtml | AK17: /
A18: 13 | B18: =C18 -> 0 | D18: 依据学考 | E18: 11113 | F18: 深圳职业技术大学 | G18: 605 | H18: 95 | I18: 114 | J18: 95 | K18: 114 | L18: 387 | M18: 398 | N18: 12684 | O18: 11322 | P18: =IFERROR(AVERAGE(L18:M18),"/") -> 392.5 | Q18: =IFERROR(AVERAGE(N18:O18),"/") -> 12003 | R18: 广东省 | S18: 深圳市 | T18: 广东省 | U18: 职业本科 | V18: 广东省 | W18: 公办 | X18: 一线城市 | Y18: 省属/双高计划/高水平学校建设单位/国家级示范 | Z18: 第一类高水平学校A档示范高职 | AA18: 深圳职业技术学院1993年创建，是国内最早独立举办高等职业技术教育的院校之一。建校以来，深职院人艰苦创业，开拓进取，不断创新教育教学理念、办学体制机制和人才培养模式，创造了中国高职教育的多个第一。学校依托珠三角产业发展，秉承深圳特区改革创新精神，坚持把立德树人作为学校教育的根本任务，立足于职业教育产教融合的办学特色，各项事业取得骄人成绩，被誉为中国高职教育的“一面旗帜”。为紧密契合“中国制造2025”等国家重大战略和深圳创新驱动发展战略，学校在2016年底召开的第三次党代会工作报告中提出“三个服务、五个定位、一个率先”的战略发展目标，始终坚持为党和国家服务、为深圳经济社会发展服务、为学生健康成长成才服务，努力成为职业教育创新发展的先行者、复合式创新型高素质技术技能人才的摇篮、企业家的摇篮、深圳中小微企业技术研发中心、深圳市民终身教育学校与中国职业教育师资培训重要基地，率先建成中国特色、世界一流职业院校，为世界职业教育发展贡献“深圳模式”。////学校现有留仙洞、西丽湖、官龙山、华侨城、凤凰山五个校区，校园总面积212万平方米，学校产权校舍建筑面积57.34万平方米，其中教室10.75万平方米，图书馆5万平方米，体育馆3.34万平方米，实训实习场所10.14万平方米。现有固定资产总值23.66亿元，其中教学仪器设备总值9.58亿元,教学用计算机14525台。图书馆藏有纸质图书261.2万册，电子图书130万册，电子期刊60.54万册，中外文数据库46个，音视频16.07万小时。////全校现有教职员工2380人，其中专任教师1243人，正高217人，副高657人，博士408人，享受国务院特殊津贴专家2名，珠江学者5人、海外高层次人才25人、国家“万人计划”教学名师1人、国家级教学名师3人、省级教学名师8人、国家特支计划教师1人、广东特支计划教学名师4人。学校拥有教育部首批黄大年式教师团队1个；引进美国霍夫曼诺奖团队等一批重量级团队，成立霍夫曼先进材料研究院、智能科学与工程研究院、智能制造研究院、新时代中国职业教育研究院、社会与经济发展研究院等高端平台，为珠三角产业发展提供有力支撑。////学校设有电子与通信工程学院等17个二级学院和体育部、工业中心、国际教育部等教学单位，招生专业80个。全校普通全日制在校生22750人，其中港澳台留学生79人，四年制高职生284人，应用型本科生292人，外国留学生127人。自办专科教育在校生3536人。国家级教学成果奖14项，国家职业教育专业教学资源库3项，国家重点支持建设示范专业12个，中央财政支持实训基地9个，国家级精品教材12部，国家精品课程53门，国家级精品资源共享课43门。////学校一直把人才培养作为中心工作，以培养适应智能时代需要的复合式创新型高素质技术技能人才为目标，更新教育教学理念，探索实施以学生学习成效为导向的OBE（Outcome/Based/Education）人才培养模式改革，深入推进产教融合、职普融合、理实融合、技术与文化融合、教育与生活融合、现代信息技术与教学融合等“六个融合”，提升学生的就业能力、职业生涯拓展能力和幸福生活创造能力。瞄准未来社会和经济发展，紧贴深圳四大支柱产业和新兴产业布局专业，打造品牌专业，与华为、ARM、阿里巴巴、平安、比亚迪、裕同、天健等一流企业紧密合作，共建华为信息与网络技术学院、ARM智能硬件学院、阿里巴巴数字贸易学院、平安金融科技学院、比亚迪应用技术学院、裕同数字图文学院、天健建工学院等7所特色产业学院，校企共同制定专业标准、共同开发课程、共建师资团队、共同培养技术技能人才，在服务一流企业中成就自身一流。开设专业文化课程，大力培育工匠精神，厚植工匠文化，全面推进职业院校文化育人。学校已累计培养11万余名全日制专科毕业生，毕业生初次就业率始终保持在96%以上，多项人才培养质量指标位居全国高职院校前列，深受用人单位欢迎。其中，238人次获CCIE证书，13人获RHCA证书，57人获OCM证书，163人获HCIE证书，13人获RHCE证书。////学校探索实施创新创业教育改革，以“五维一体”的创新创业教育理念（重心在“教育”、路径在“分层”、目标在“万众”、核心在“创新”、关键在“实践”）为引领，打造深圳中小微企业技术研发中心、全球技术技能人才创新创业教育中心，以及创新型人才和企业家培养的成长摇篮。通过系统设计、科学构建，协同推进从启蒙教育、预科教育、专门教育到指导创办企业的进阶式创业人才培养体系，搭建“四会两赛三联盟”双创交流平台和“创新型社团—创客中心—学生创意创业园”双创实践平台，逐步完善跨界融合、产品试制、创业孵化、创业投资的双创服务体系，取得良好的社会效益。近年来获评首批全国创新创业典型经验高校、全国深化创新创业教育改革示范高校、广东省大众创业万众创新示范基地、深圳首批十大创新创业基地等。近四届毕业生毕业一年内自主创业比例达到5%，毕业三年后创业比例12.7%。////学校坚持以“产学研用”一体化的科研导向，重视技术转移和科技成果转化。近年来，学校不断深化科研体制机制改革，大力加强与政府职能部门以及行业企业合作，组建成立了应用技术研发院、文化创意产品研发院、经济与社会发展研究院等三大综合性研发平台，建成43个市区级以上科研平台,抢抓产业发展新机遇，服务地方经济社会和中小企业发展。全校累计承担各级各类科研课题5196项，其中国家级项目84项,年度新增国家自然科学基金项目10项。科研经费到账总经费达到8.06亿元，其中技术转移（横向科研）项目到账经费2.98亿元；出版各类学术专著226部、编著、译著和作品集共199部，61项科研成果获部、省、市级奖励；获国家专利授权1726项，软件著作权登记1136件，发明专利345项。主导或参与制定国际、国家、行业标准74项。////学校重视社会服务，发挥品牌优势，致力于推动现代职业教育培训体系和学习型社会建设。做好高水平师资培训，打造世界级的职业教育培训中心；做好职业培训、职业技能鉴定及职业资格认证工作，服务好地方经济发展需要；联合社区街道组建社区学院、特色学院，开展针对社区居民的健康、养老、旅游等培训项目，服务好地方社会发展需要；以办学理念和教学模式输出为主要内容，构建“理念—教学—师资—管理”四位一体的精准帮扶体系，服务好对口支援地区和院校的发展。全年重点对口帮扶11所职业院校，累计对口支援西藏、新疆、贵州等地11个省、自治区的200余所职业院校。全年举办33个全国高职高专师资培训班，累计为全国680余所职业院校培训骨干教师1.2万人次，连续5年名列全国第一。年均开展各类培训、职业技能鉴定与资格认证12万人次。组建西丽社区学院、大鹏旅游学院等社区学院，与社区共同培养技能人才，打造开放办学、产教融合的“职教特区”；选派核心团队建设管理吉安职业技术学院，开创了特区与老区携手共同发展职业教育的典范。////学校紧扣国家发展战略，加快国际化办学步伐，充分利用区域与自身优势，深化国际教育交流与合作。建校以来，已累计与32个国家和地区的162所高校和教育机构建立了友好合作关系，包括英国、德国、法国、美国等发达国家以及新西兰、马来西亚、保加利亚、土耳其、波兰、匈牙利、缅甸、老挝等14个“一带一路”沿线国家。双方在学生交换、课程合作、科研合作、短期研修等领域开展了全方位、多层次、形式多样的教师和学生国际交流活动，取得了丰硕的成果。近年来，我校年均接待境外来访师生及外宾108批次，658人次；我校赴境外参加国际交流的师生52批次，276人次。开办了国际商务（中澳）、金融管理（中澳）、物流管理（中美）和软件技术（中美）4个中外合作办学专业；与香港专业教育学院黄克竞分校合办电气服务工程高级文凭合作课程，毕业生获得深港两地毕业资格，并成为首批获得招收海外留学生资质的高职院校和首个获批面向港澳台自主招生的高职院校。学校还联合中兴、招商港口等一批世界一流企业“走出去”，服务国家“一带一路”倡议。在马来西亚马六甲应用技术大学设立职业教育与培训中心，推动马来西亚全国各类职业院校全面对接深职院标准。依托在保加利亚成立的职业教育与培训中心，输出学校专业标准。应邀为柬埔寨、蒙古等国家职业教育代表团举行专题培训班，输出职业教育经验。加强与职业教育国际组织的合作，成为联合国教科文组织国际职教全球联系中心之一，获批成立联合国教科文组织职业教育计划亚非研究与培训中心。在提高学校国际知名度与影响力的同时，为推动中国职业教育与语言文化走出去做出了积极贡献。////学校办学成绩显著。2001年首家通过国家示范性高职院校实践教学基地优秀评估，2009年通过国家示范性高等职业院校建设项目验收，成为我国高等职业教育领域首批国家级示范校。近年来，学校先后荣获“全国文明单位”、“全国职业教育先进单位”、“全国一流高职院校建设单位”、“首批全国创新创业典型经验高校”、“全国高校毕业生就业工作先进集体”、“中国十大最具就业力高职院校”、“全国毕业生就业工作典型经验高校”、“全国职业院校就业竞争力示范校”、“中国十大创新型高职院校”、“黄炎培优秀学校奖”、“全国高校实践育人创新创业基地”“广东省文明单位”、“广东省职业技术教育工作先进集体”、“广东省首批大学生创新创业教育示范学校”、“广东省一流高职院校建设单位”“深圳市创新创业基地”等荣誉称号。 | AB18: 深圳职业技术大学于1993年创建，前身为深圳职业技术学院，是中国国内最早独立举办高等职业技术教育的院校之一。2000年、2004年原深圳市职业技术学校、深圳市卫生学校分别并入深圳职业技术学院。2006年深圳职业技术学院被确定为“国家示范性高等职业院校建设计划”首批立项建设院校，2009年学校顺利通过验收成为首批国家示范性高等职业院校。2023年6月，教育部发文同意以深圳职业技术学院为基础整合资源设立深圳职业技术大学，同时撤销深圳职业技术学院的建制。 | AC18: http://www.szpt.edu.cn/ | AD18: https://zhaosheng.szpt.edu.cn/ | AE18: 0755/26731715、26731216 | AF18: 深圳市南山区西丽街道留仙大道7098号 | AG18: https://www.720yun.com/t/d8vksm7e0d9 | AH18: 158 | AI18: https://baike.baidu.com/item/%E6%B7%B1%E5%9C%B3%E8%81%8C%E4%B8%9A%E6%8A%80%E6%9C%AF%E5%A4%A7%E5%AD%A6 | AJ18: https://gaokao.chsi.com.cn/zsgs/zhangcheng/listZszc//schId/734.dhtml | AK18: /
